<?xml version="1.0" ?>
<!-- =================================================================================== -->
<!-- |    This document was autogenerated by xacro from src/mulinex_description/urdf/mulinex.xacro | -->
<!-- |    EDITING THIS FILE BY HAND IS NOT RECOMMENDED                                 | -->
<!-- =================================================================================== -->
<robot name="mulinex">
  <!-- <xacro:property name="base_2_HFE_x" value="${190.00 * 0.001}" /> -->
  <!-- <xacro:property name="base_2_HFE_y" value="${104.60 * 0.001}" /> -->
  <!--  -->
  <!-- EACH MACRO CONSISTS OF THE LINK AND ITS PREVIOUS JOINT -->
  <!--  -->
  <!-- <xacro:property name="base_2_HFE_x" value="${190.00 * 0.001}" /> -->
  <!-- <xacro:property name="base_2_HFE_y" value="${104.60 * 0.001}" /> -->
  <!--  -->
  <!-- EACH MACRO CONSISTS OF THE LINK AND ITS PREVIOUS JOINT -->
  <!--  -->
  <material name="black">
    <color rgba="0.0 0.0 0.0 1.0"/>
  </material>
  <material name="blue">
    <color rgba="0.0 0.0 0.8 1.0"/>
  </material>
  <material name="green">
    <color rgba="0.0 0.8 0.0 1.0"/>
  </material>
  <material name="grey">
    <color rgba="0.2 0.2 0.2 1.0"/>
  </material>
  <material name="orange">
    <color rgba="1.0 0.4235294117647059 0.0392156862745098 0.5"/>
  </material>
  <material name="brown">
    <color rgba="0.8705882352941177 0.8117647058823529 0.7647058823529411 1.0"/>
  </material>
  <material name="red">
    <color rgba="0.8 0.0 0.0 1.0"/>
  </material>
  <material name="white">
    <color rgba="1.0 1.0 1.0 1.0"/>
  </material>
  <link name="base_link">
    <visual>
      <material name="white"/>
      <origin rpy="0 0 0" xyz="0 0 0"/>
      <geometry>
        <mesh filename="file:///home/jacopo/Documents/mul_pronto_ws/install/mulinex_description/share/mulinex_description/meshes//Body.stl"/>
        <!-- <box size="0.353 0.090 0.066" /> -->
      </geometry>
    </visual>
    <collision>
      <origin rpy="0 0 0" xyz="0 0 0"/>
      <geometry>
        <box size="0.353 0.090 0.066"/>
      </geometry>
    </collision>
    <inertial>
      <mass value="1.3008737"/>
      <origin rpy="0 0 0" xyz="-1.4565496e-03 -2.5110071e-03 -4.2484136e-03"/>
      <inertia ixx="4.0762590e-03" ixy="-2.5234809e-05" ixz="-3.2587794e-06" iyy="9.2413606e-03" iyz="-8.0660183e-06" izz="1.2268730e-02"/>
    </inertial>
  </link>
  <!-- Joint to fix the leg to the base -->
  <joint name="LH_HAA" type="fixed">
    <parent link="base_link"/>
    <child link="LH_SHOULDER"/>
    <origin rpy="0 0 0" xyz="-0.045 0.081 0"/>
  </joint>
  <!-- Shoulder link -->
  <link name="LH_SHOULDER">
    <visual>
      <material name="white"/>
      <origin rpy="0 0 0" xyz="0 0 0"/>
      <geometry>
        <mesh filename="file:///home/jacopo/Documents/mul_pronto_ws/install/mulinex_description/share/mulinex_description/meshes//Module_left_hind.stl"/>
      </geometry>
    </visual>
    <collision>
      <origin rpy="0 0 0" xyz="-0.0945 0 0"/>
      <geometry>
        <!-- <mesh filename="${mulinex_module_left_hind}" /> -->
        <box size="0.269 0.057 0.060"/>
      </geometry>
    </collision>
    <inertial>
      <mass value="0.47669673"/>
      <origin rpy="0 0 0" xyz="-7.2487360e-02 3.1582591e-02 2.4812434e-03"/>
      <inertia ixx="2.1574269e-04" ixy="3.3437484e-05" ixz="-2.4284668e-06" iyy="3.0607390e-03" iyz="-2.0388977e-06" izz="3.0504273e-03"/>
    </inertial>
  </link>
  <gazebo reference="LH_SHOULDER">
    <material>Gazebo/White</material>
    <collision>
      <surface>
        <friction>
          <ode>
            <mu>1</mu>
            <mu2>1</mu2>
            <slip1>0</slip1>
            <slip2>0</slip2>
          </ode>
        </friction>
        <contact>
          <ode>
            <kp>1000000.0</kp>
            <kd>100.0</kd>
            <min_depth>0.001</min_depth>
          </ode>
        </contact>
      </surface>
    </collision>
  </gazebo>
  <!-- Hip joint -->
  <joint name="LH_HFE" type="revolute">
    <parent link="LH_SHOULDER"/>
    <child link="LH_UPPER_LEG"/>
    <origin rpy="0 0 0" xyz="-0.19 0.044 0"/>
    <axis xyz="0 1 0"/>
    <limit effort="2.7" lower="-3.141592" upper="3.141592" velocity="1000"/>
    <!-- <dynamics damping="0.7" friction="100.0" /> -->
  </joint>
  <!-- Upper leg link -->
  <link name="LH_UPPER_LEG">
    <visual>
      <material name="white"/>
      <origin rpy="0 0 0" xyz="0 0 0"/>
      <geometry>
        <mesh filename="file:///home/jacopo/Documents/mul_pronto_ws/install/mulinex_description/share/mulinex_description/meshes//Module_left_hind.stl"/>
      </geometry>
    </visual>
    <collision>
      <origin rpy="0 0 0" xyz="-0.0945 0.015 0"/>
      <geometry>
        <!-- <mesh filename="${mulinex_module_left_hind}" /> -->
        <box size="0.269 0.057 0.060"/>
      </geometry>
    </collision>
    <inertial>
      <mass value="0.47669673"/>
      <origin rpy="0 0 0" xyz="-7.2487360e-02 3.1582591e-02 2.4812434e-03"/>
      <inertia ixx="2.1574269e-04" ixy="3.3437484e-05" ixz="-2.4284668e-06" iyy="3.0607390e-03" iyz="-2.0388977e-06" izz="3.0504273e-03"/>
    </inertial>
  </link>
  <gazebo reference="LH_UPPER_LEG">
    <material>Gazebo/White</material>
    <collision>
      <surface>
        <friction>
          <ode>
            <mu>1</mu>
            <mu2>1</mu2>
            <slip1>0</slip1>
            <slip2>0</slip2>
          </ode>
        </friction>
        <contact>
          <ode>
            <kp>1000000.0</kp>
            <kd>100.0</kd>
            <min_depth>0.001</min_depth>
          </ode>
        </contact>
      </surface>
    </collision>
  </gazebo>
  <!-- Knee joint -->
  <joint name="LH_KFE" type="revolute">
    <parent link="LH_UPPER_LEG"/>
    <child link="LH_LOWER_LEG"/>
    <origin rpy="0 0 0" xyz="-0.19 0.044 0"/>
    <axis xyz="0 1 0"/>
    <limit effort="2.7" lower="-3.141592" upper="3.141592" velocity="1000"/>
    <!-- <dynamics damping="0.7" friction="100.0" /> -->
  </joint>
  <!-- Lower leg link -->
  <link name="LH_LOWER_LEG">
    <visual>
      <material name="white"/>
      <origin rpy="0 1.570796 0" xyz="0 0 0"/>
      <geometry>
        <mesh filename="file:///home/jacopo/Documents/mul_pronto_ws/install/mulinex_description/share/mulinex_description/meshes//Lower_leg_left.stl"/>
      </geometry>
    </visual>
    <collision name="LH_LOWER_LEG">
      <origin rpy="0 1.570796 0" xyz="-0.096 0.012 0.0"/>
      <geometry>
        <box size="0.032 0.024 0.192"/>
      </geometry>
    </collision>
    <inertial>
      <mass value="0.046942"/>
      <origin rpy="0 0 0" xyz="-0.0660893 0.0198901 1.552593e-05"/>
      <inertia ixx="5.140780e-06" ixy="-1.089102e-05" ixz="2.46811e-08" iyy="0.0002124295" iyz="-2.702972e-09" izz="0.0002115478"/>
    </inertial>
  </link>
  <gazebo reference="LH_LOWER_LEG">
    <material>Gazebo/White</material>
    <collision>
      <surface>
        <friction>
          <ode>
            <mu>0.6</mu>
            <mu2>0.6</mu2>
            <slip1>0</slip1>
            <slip2>0</slip2>
          </ode>
        </friction>
        <contact>
          <ode>
            <kp>10000.0</kp>
            <kd>100.0</kd>
            <min_depth>0.001</min_depth>
          </ode>
        </contact>
      </surface>
    </collision>
  </gazebo>
  <joint name="LH_ANKLE" type="fixed">
    <parent link="LH_LOWER_LEG"/>
    <child link="LH_FOOT"/>
    <origin rpy="0 0 0" xyz="-0.19 0.028 0"/>
  </joint>
  <link name="LH_FOOT">
    <collision>
      <origin rpy="0 0 0" xyz="0 0 0"/>
      <geometry>
        <sphere radius="0.015"/>
      </geometry>
    </collision>
  </link>
  <gazebo reference="LH_FOOT">
    <material>Gazebo/White</material>
    <collision>
      <surface>
        <friction>
          <ode>
            <mu>0.6</mu>
            <mu2>0.6</mu2>
            <slip1>0</slip1>
            <slip2>0</slip2>
          </ode>
        </friction>
        <contact>
          <ode>
            <kp>10000.0</kp>
            <kd>100.0</kd>
            <min_depth>0.001</min_depth>
          </ode>
        </contact>
      </surface>
    </collision>
    <sensor name="LH_contactsensor_sensor" type="contact">
      <always_on>true</always_on>
      <update_rate>50</update_rate>
      <contact>
        <collision>
                                LH_LOWER_LEG_fixed_joint_lump__LH_FOOT_collision_1</collision>
      </contact>
    </sensor>
  </gazebo>
  <!-- Joint to fix the leg to the base -->
  <joint name="LF_HAA" type="fixed">
    <parent link="base_link"/>
    <child link="LF_SHOULDER"/>
    <origin rpy="0 0 0" xyz="0.045 0.081 0"/>
  </joint>
  <!-- Shoulder link -->
  <link name="LF_SHOULDER">
    <visual>
      <material name="white"/>
      <origin rpy="0 0 0" xyz="0 0 0"/>
      <geometry>
        <mesh filename="file:///home/jacopo/Documents/mul_pronto_ws/install/mulinex_description/share/mulinex_description/meshes//Module_left_front.stl"/>
      </geometry>
    </visual>
    <collision>
      <origin rpy="0 0 0" xyz="0.0945 0 0"/>
      <geometry>
        <!-- <mesh filename="${mulinex_module_left_front}" /> -->
        <box size="0.269 0.057 0.060"/>
      </geometry>
    </collision>
    <inertial>
      <mass value="0.47669673"/>
      <origin rpy="0 0 0" xyz="7.2487360e-02 3.1582591e-02 -2.4812434e-03"/>
      <inertia ixx="2.1574269e-04" ixy="-3.3437484e-05" ixz="-2.4284668e-06" iyy="3.0607390e-03" iyz="-2.0388977e-06" izz="3.0504273e-03"/>
    </inertial>
  </link>
  <gazebo reference="LF_SHOULDER">
    <material>Gazebo/White</material>
    <collision>
      <surface>
        <friction>
          <ode>
            <mu>1</mu>
            <mu2>1</mu2>
            <slip1>0</slip1>
            <slip2>0</slip2>
          </ode>
        </friction>
        <contact>
          <ode>
            <kp>1000000.0</kp>
            <kd>100.0</kd>
            <min_depth>0.001</min_depth>
          </ode>
        </contact>
      </surface>
    </collision>
  </gazebo>
  <!-- Hip joint -->
  <joint name="LF_HFE" type="revolute">
    <parent link="LF_SHOULDER"/>
    <child link="LF_UPPER_LEG"/>
    <origin rpy="0 0 0" xyz="0.19 0.044 0"/>
    <axis xyz="0 1 0"/>
    <limit effort="2.7" lower="-3.141592" upper="3.141592" velocity="1000"/>
    <!-- <dynamics damping="0.7" friction="100.0" /> -->
  </joint>
  <!-- Upper leg link -->
  <link name="LF_UPPER_LEG">
    <visual>
      <material name="white"/>
      <origin rpy="0 0 0" xyz="0 0 0"/>
      <geometry>
        <mesh filename="file:///home/jacopo/Documents/mul_pronto_ws/install/mulinex_description/share/mulinex_description/meshes//Module_left_front.stl"/>
      </geometry>
    </visual>
    <collision>
      <origin rpy="0 0 0" xyz="0.0945 0.015 0"/>
      <geometry>
        <!-- <mesh filename="${mulinex_module_left_front}" /> -->
        <box size="0.269 0.057 0.060"/>
      </geometry>
    </collision>
    <inertial>
      <mass value="0.47669673"/>
      <origin rpy="0 0 0" xyz="7.2487360e-02 3.1582591e-02 -2.4812434e-03"/>
      <inertia ixx="2.1574269e-04" ixy="-3.3437484e-05" ixz="-2.4284668e-06" iyy="3.0607390e-03" iyz="-2.0388977e-06" izz="3.0504273e-03"/>
    </inertial>
  </link>
  <gazebo reference="LF_UPPER_LEG">
    <material>Gazebo/White</material>
    <collision>
      <surface>
        <friction>
          <ode>
            <mu>1</mu>
            <mu2>1</mu2>
            <slip1>0</slip1>
            <slip2>0</slip2>
          </ode>
        </friction>
        <contact>
          <ode>
            <kp>1000000.0</kp>
            <kd>100.0</kd>
            <min_depth>0.001</min_depth>
          </ode>
        </contact>
      </surface>
    </collision>
  </gazebo>
  <!-- Knee joint -->
  <joint name="LF_KFE" type="revolute">
    <parent link="LF_UPPER_LEG"/>
    <child link="LF_LOWER_LEG"/>
    <origin rpy="0 0 0" xyz="0.19 0.044 0"/>
    <axis xyz="0 1 0"/>
    <limit effort="2.7" lower="-3.141592" upper="3.141592" velocity="1000"/>
    <!-- <dynamics damping="0.7" friction="100.0" /> -->
  </joint>
  <!-- Lower leg link -->
  <link name="LF_LOWER_LEG">
    <visual>
      <material name="white"/>
      <origin rpy="0 -1.570796 0" xyz="0 0 0"/>
      <geometry>
        <mesh filename="file:///home/jacopo/Documents/mul_pronto_ws/install/mulinex_description/share/mulinex_description/meshes//Lower_leg_left.stl"/>
      </geometry>
    </visual>
    <collision name="LF_LOWER_LEG">
      <origin rpy="0 -1.570796 0" xyz="0.096 0.012 0.0"/>
      <geometry>
        <box size="0.032 0.024 0.192"/>
      </geometry>
    </collision>
    <inertial>
      <mass value="0.046942"/>
      <origin rpy="0 0 0" xyz="0.0660893 0.0198901 -1.552593e-05"/>
      <inertia ixx="5.140780e-06" ixy="1.089102e-05" ixz="2.468115e-08" iyy="0.00021242" iyz="2.702972e-09" izz="0.00021154"/>
    </inertial>
  </link>
  <gazebo reference="LF_LOWER_LEG">
    <material>Gazebo/White</material>
    <collision>
      <surface>
        <friction>
          <ode>
            <mu>0.6</mu>
            <mu2>0.6</mu2>
            <slip1>0</slip1>
            <slip2>0</slip2>
          </ode>
        </friction>
        <contact>
          <ode>
            <kp>10000.0</kp>
            <kd>100.0</kd>
            <min_depth>0.001</min_depth>
          </ode>
        </contact>
      </surface>
    </collision>
  </gazebo>
  <joint name="LF_ANKLE" type="fixed">
    <parent link="LF_LOWER_LEG"/>
    <child link="LF_FOOT"/>
    <origin rpy="0 0 0" xyz="0.19 0.028 0"/>
  </joint>
  <link name="LF_FOOT">
    <collision>
      <origin rpy="0 0 0" xyz="0 0 0"/>
      <geometry>
        <sphere radius="0.015"/>
      </geometry>
    </collision>
  </link>
  <gazebo reference="LF_FOOT">
    <material>Gazebo/White</material>
    <collision>
      <surface>
        <friction>
          <ode>
            <mu>0.6</mu>
            <mu2>0.6</mu2>
            <slip1>0</slip1>
            <slip2>0</slip2>
          </ode>
        </friction>
        <contact>
          <ode>
            <kp>10000.0</kp>
            <kd>100.0</kd>
            <min_depth>0.001</min_depth>
          </ode>
        </contact>
      </surface>
    </collision>
    <sensor name="LF_contactsensor_sensor" type="contact">
      <always_on>true</always_on>
      <update_rate>50</update_rate>
      <contact>
        <collision>
                                LF_LOWER_LEG_fixed_joint_lump__LF_FOOT_collision_1</collision>
      </contact>
    </sensor>
  </gazebo>
  <!-- Joint to fix the leg to the base -->
  <joint name="RF_HAA" type="fixed">
    <parent link="base_link"/>
    <child link="RF_SHOULDER"/>
    <origin rpy="0 0 0" xyz="0.045 -0.081 0"/>
  </joint>
  <!-- Shoulder link -->
  <link name="RF_SHOULDER">
    <visual>
      <material name="white"/>
      <origin rpy="0 0 0" xyz="0 0 0"/>
      <geometry>
        <mesh filename="file:///home/jacopo/Documents/mul_pronto_ws/install/mulinex_description/share/mulinex_description/meshes//Module_right_front.stl"/>
      </geometry>
    </visual>
    <collision>
      <origin rpy="0 0 0" xyz="0.0945 0 0"/>
      <geometry>
        <!-- <mesh filename="${mulinex_module_right_front}" /> -->
        <box size="0.269 0.057 0.060"/>
      </geometry>
    </collision>
    <inertial>
      <mass value="0.47669673"/>
      <origin rpy="0 0 0" xyz="7.2487360e-02 -3.1582591e-02 2.4812434e-03"/>
      <inertia ixx="2.1574269e-04" ixy="3.3437484e-05" ixz="2.4284668e-06" iyy="3.0607390e-03" iyz="-2.0388977e-06" izz="3.0504273e-03"/>
    </inertial>
  </link>
  <gazebo reference="RF_SHOULDER">
    <material>Gazebo/White</material>
    <collision>
      <surface>
        <friction>
          <ode>
            <mu>1</mu>
            <mu2>1</mu2>
            <slip1>0</slip1>
            <slip2>0</slip2>
          </ode>
        </friction>
        <contact>
          <ode>
            <kp>1000000.0</kp>
            <kd>100.0</kd>
            <min_depth>0.001</min_depth>
          </ode>
        </contact>
      </surface>
    </collision>
  </gazebo>
  <!-- Hip joint -->
  <joint name="RF_HFE" type="revolute">
    <parent link="RF_SHOULDER"/>
    <child link="RF_UPPER_LEG"/>
    <origin rpy="0 0 0" xyz="0.19 -0.044 0"/>
    <axis xyz="0 -1 0"/>
    <limit effort="2.7" lower="-3.141592" upper="3.141592" velocity="1000"/>
    <!-- <dynamics damping="0.7" friction="100.0" /> -->
  </joint>
  <!-- Upper leg link -->
  <link name="RF_UPPER_LEG">
    <visual>
      <material name="white"/>
      <origin rpy="0 0 0" xyz="0 0 0"/>
      <geometry>
        <mesh filename="file:///home/jacopo/Documents/mul_pronto_ws/install/mulinex_description/share/mulinex_description/meshes//Module_right_front.stl"/>
      </geometry>
    </visual>
    <collision>
      <origin rpy="0 0 0" xyz="0.0945 -0.015 0"/>
      <geometry>
        <!-- <mesh filename="${mulinex_module_right_front}" /> -->
        <box size="0.269 0.057 0.060"/>
      </geometry>
    </collision>
    <inertial>
      <mass value="0.47669673"/>
      <origin rpy="0 0 0" xyz="7.2487360e-02 -3.1582591e-02 2.4812434e-03"/>
      <inertia ixx="2.1574269e-04" ixy="3.3437484e-05" ixz="2.4284668e-06" iyy="3.0607390e-03" iyz="-2.0388977e-06" izz="3.0504273e-03"/>
    </inertial>
  </link>
  <gazebo reference="RF_UPPER_LEG">
    <material>Gazebo/White</material>
    <collision>
      <surface>
        <friction>
          <ode>
            <mu>1</mu>
            <mu2>1</mu2>
            <slip1>0</slip1>
            <slip2>0</slip2>
          </ode>
        </friction>
        <contact>
          <ode>
            <kp>1000000.0</kp>
            <kd>100.0</kd>
            <min_depth>0.001</min_depth>
          </ode>
        </contact>
      </surface>
    </collision>
  </gazebo>
  <!-- Knee joint -->
  <joint name="RF_KFE" type="revolute">
    <parent link="RF_UPPER_LEG"/>
    <child link="RF_LOWER_LEG"/>
    <origin rpy="0 0 0" xyz="0.19 -0.044 0"/>
    <axis xyz="0 -1 0"/>
    <limit effort="2.7" lower="-3.141592" upper="3.141592" velocity="1000"/>
    <!-- <dynamics damping="0.7" friction="100.0" /> -->
  </joint>
  <!-- Lower leg link -->
  <link name="RF_LOWER_LEG">
    <visual>
      <material name="white"/>
      <origin rpy="0 -1.570796 0" xyz="0 0 0"/>
      <geometry>
        <mesh filename="file:///home/jacopo/Documents/mul_pronto_ws/install/mulinex_description/share/mulinex_description/meshes//Lower_leg_right.stl"/>
      </geometry>
    </visual>
    <collision name="RF_LOWER_LEG">
      <origin rpy="0 -1.570796 0" xyz="0.096 -0.012 0.0"/>
      <geometry>
        <box size="0.032 0.024 0.192"/>
      </geometry>
    </collision>
    <inertial>
      <mass value="0.046942"/>
      <origin rpy="0 0 0" xyz="0.0660893 -0.0198901 -1.552593e-05"/>
      <inertia ixx="5.140780e-06" ixy="1.089102e-05" ixz="-2.468115e-08" iyy="0.00021242" iyz="-2.702972e-09" izz="0.00021154"/>
    </inertial>
  </link>
  <gazebo reference="RF_LOWER_LEG">
    <material>Gazebo/White</material>
    <collision>
      <surface>
        <friction>
          <ode>
            <mu>0.6</mu>
            <mu2>0.6</mu2>
            <slip1>0</slip1>
            <slip2>0</slip2>
          </ode>
        </friction>
        <contact>
          <ode>
            <kp>10000.0</kp>
            <kd>100.0</kd>
            <min_depth>0.001</min_depth>
          </ode>
        </contact>
      </surface>
    </collision>
  </gazebo>
  <joint name="RF_ANKLE" type="fixed">
    <parent link="RF_LOWER_LEG"/>
    <child link="RF_FOOT"/>
    <origin rpy="0 0 0" xyz="0.19 -0.028 0"/>
  </joint>
  <link name="RF_FOOT">
    <collision>
      <origin rpy="0 0 0" xyz="0 0 0"/>
      <geometry>
        <sphere radius="0.015"/>
      </geometry>
    </collision>
  </link>
  <gazebo reference="RF_FOOT">
    <material>Gazebo/White</material>
    <collision>
      <surface>
        <friction>
          <ode>
            <mu>0.6</mu>
            <mu2>0.6</mu2>
            <slip1>0</slip1>
            <slip2>0</slip2>
          </ode>
        </friction>
        <contact>
          <ode>
            <kp>10000.0</kp>
            <kd>100.0</kd>
            <min_depth>0.001</min_depth>
          </ode>
        </contact>
      </surface>
    </collision>
    <sensor name="RF_contactsensor_sensor" type="contact">
      <always_on>true</always_on>
      <update_rate>50</update_rate>
      <contact>
        <collision>
                                RF_LOWER_LEG_fixed_joint_lump__RF_FOOT_collision_1</collision>
      </contact>
    </sensor>
  </gazebo>
  <!-- Joint to fix the leg to the base -->
  <joint name="RH_HAA" type="fixed">
    <parent link="base_link"/>
    <child link="RH_SHOULDER"/>
    <origin rpy="0 0 0" xyz="-0.045 -0.081 0"/>
  </joint>
  <!-- Shoulder link -->
  <link name="RH_SHOULDER">
    <visual>
      <material name="white"/>
      <origin rpy="0 0 0" xyz="0 0 0"/>
      <geometry>
        <mesh filename="file:///home/jacopo/Documents/mul_pronto_ws/install/mulinex_description/share/mulinex_description/meshes//Module_right_hind.stl"/>
      </geometry>
    </visual>
    <collision>
      <origin rpy="0 0 0" xyz="-0.0945 0 0"/>
      <geometry>
        <!-- <mesh filename="${mulinex_module_right_hind}" /> -->
        <box size="0.269 0.057 0.060"/>
      </geometry>
    </collision>
    <inertial>
      <mass value="0.47669673"/>
      <origin rpy="0 0 0" xyz="-7.2487360e-02 -3.1582591e-02 -2.4812434e-03"/>
      <inertia ixx="2.1574269e-04" ixy="-3.3437484e-05" ixz="2.4284668e-06" iyy="3.0607390e-03" iyz="-2.0388977e-06" izz="3.0504273e-03"/>
    </inertial>
  </link>
  <gazebo reference="RH_SHOULDER">
    <material>Gazebo/White</material>
    <collision>
      <surface>
        <friction>
          <ode>
            <mu>1</mu>
            <mu2>1</mu2>
            <slip1>0</slip1>
            <slip2>0</slip2>
          </ode>
        </friction>
        <contact>
          <ode>
            <kp>1000000.0</kp>
            <kd>100.0</kd>
            <min_depth>0.001</min_depth>
          </ode>
        </contact>
      </surface>
    </collision>
  </gazebo>
  <!-- Hip joint -->
  <joint name="RH_HFE" type="revolute">
    <parent link="RH_SHOULDER"/>
    <child link="RH_UPPER_LEG"/>
    <origin rpy="0 0 0" xyz="-0.19 -0.044 0"/>
    <axis xyz="0 -1 0"/>
    <limit effort="2.7" lower="-3.141592" upper="3.141592" velocity="1000"/>
    <!-- <dynamics damping="0.7" friction="100.0" /> -->
  </joint>
  <!-- Upper leg link -->
  <link name="RH_UPPER_LEG">
    <visual>
      <material name="white"/>
      <origin rpy="0 0 0" xyz="0 0 0"/>
      <geometry>
        <mesh filename="file:///home/jacopo/Documents/mul_pronto_ws/install/mulinex_description/share/mulinex_description/meshes//Module_right_hind.stl"/>
      </geometry>
    </visual>
    <collision>
      <origin rpy="0 0 0" xyz="-0.0945 -0.015 0"/>
      <geometry>
        <!-- <mesh filename="${mulinex_module_right_hind}" /> -->
        <box size="0.269 0.057 0.060"/>
      </geometry>
    </collision>
    <inertial>
      <mass value="0.47669673"/>
      <origin rpy="0 0 0" xyz="-7.2487360e-02 -3.1582591e-02 -2.4812434e-03"/>
      <inertia ixx="2.1574269e-04" ixy="-3.3437484e-05" ixz="2.4284668e-06" iyy="3.0607390e-03" iyz="-2.0388977e-06" izz="3.0504273e-03"/>
    </inertial>
  </link>
  <gazebo reference="RH_UPPER_LEG">
    <material>Gazebo/White</material>
    <collision>
      <surface>
        <friction>
          <ode>
            <mu>1</mu>
            <mu2>1</mu2>
            <slip1>0</slip1>
            <slip2>0</slip2>
          </ode>
        </friction>
        <contact>
          <ode>
            <kp>1000000.0</kp>
            <kd>100.0</kd>
            <min_depth>0.001</min_depth>
          </ode>
        </contact>
      </surface>
    </collision>
  </gazebo>
  <!-- Knee joint -->
  <joint name="RH_KFE" type="revolute">
    <parent link="RH_UPPER_LEG"/>
    <child link="RH_LOWER_LEG"/>
    <origin rpy="0 0 0" xyz="-0.19 -0.044 0"/>
    <axis xyz="0 -1 0"/>
    <limit effort="2.7" lower="-3.141592" upper="3.141592" velocity="1000"/>
    <!-- <dynamics damping="0.7" friction="100.0" /> -->
  </joint>
  <!-- Lower leg link -->
  <link name="RH_LOWER_LEG">
    <visual>
      <material name="white"/>
      <origin rpy="0 1.570796 0" xyz="0 0 0"/>
      <geometry>
        <mesh filename="file:///home/jacopo/Documents/mul_pronto_ws/install/mulinex_description/share/mulinex_description/meshes//Lower_leg_right.stl"/>
      </geometry>
    </visual>
    <collision name="RH_LOWER_LEG">
      <origin rpy="0 1.570796 0" xyz="-0.096 -0.012 0.0"/>
      <geometry>
        <box size="0.032 0.024 0.192"/>
      </geometry>
    </collision>
    <inertial>
      <mass value="0.046942"/>
      <origin rpy="0 0 0" xyz="-0.0660893 -0.0198901 1.552593e-05"/>
      <inertia ixx="5.140780e-06" ixy="-1.089102e-05" ixz="-2.46811e-08" iyy="0.0002124295" iyz="2.702972e-09" izz="0.0002115478"/>
    </inertial>
  </link>
  <gazebo reference="RH_LOWER_LEG">
    <material>Gazebo/White</material>
    <collision>
      <surface>
        <friction>
          <ode>
            <mu>0.6</mu>
            <mu2>0.6</mu2>
            <slip1>0</slip1>
            <slip2>0</slip2>
          </ode>
        </friction>
        <contact>
          <ode>
            <kp>10000.0</kp>
            <kd>100.0</kd>
            <min_depth>0.001</min_depth>
          </ode>
        </contact>
      </surface>
    </collision>
  </gazebo>
  <joint name="RH_ANKLE" type="fixed">
    <parent link="RH_LOWER_LEG"/>
    <child link="RH_FOOT"/>
    <origin rpy="0 0 0" xyz="-0.19 -0.028 0"/>
  </joint>
  <link name="RH_FOOT">
    <collision>
      <origin rpy="0 0 0" xyz="0 0 0"/>
      <geometry>
        <sphere radius="0.015"/>
      </geometry>
    </collision>
  </link>
  <gazebo reference="RH_FOOT">
    <material>Gazebo/White</material>
    <collision>
      <surface>
        <friction>
          <ode>
            <mu>0.6</mu>
            <mu2>0.6</mu2>
            <slip1>0</slip1>
            <slip2>0</slip2>
          </ode>
        </friction>
        <contact>
          <ode>
            <kp>10000.0</kp>
            <kd>100.0</kd>
            <min_depth>0.001</min_depth>
          </ode>
        </contact>
      </surface>
    </collision>
    <sensor name="RH_contactsensor_sensor" type="contact">
      <always_on>true</always_on>
      <update_rate>50</update_rate>
      <contact>
        <collision>
                                RH_LOWER_LEG_fixed_joint_lump__RH_FOOT_collision_1</collision>
      </contact>
    </sensor>
  </gazebo>
  <gazebo reference="base_link">
    <material>Gazebo/White</material>
  </gazebo>
  <gazebo>
    <plugin filename="libgazebo_ros2_control.so" name="gazebo_ros2_control">
      <parameters>/home/jacopo/Documents/mul_pronto_ws/install/mulinex_gazebo/share/mulinex_gazebo/config/mulinex_gazebo_sim_jnt_PD_IMU.yaml</parameters>
    </plugin>
  </gazebo>
  <ros2_control name="GazeboSystem" type="system">
    <hardware>
      <plugin>gazebo_ros2_control/GazeboSystem</plugin>
    </hardware>
    <joint name="LH_HAA">
      <command_interface name="effort"/>
      <state_interface name="position">
        <param name="initial_value">-0.0</param>
      </state_interface>
      <state_interface name="velocity">
        <param name="initial_value">0.0</param>
      </state_interface>
      <state_interface name="effort"/>
    </joint>
    <joint name="LH_HFE">
      <command_interface name="effort"/>
      <state_interface name="position">
        <param name="initial_value">0.0</param>
      </state_interface>
      <state_interface name="velocity">
        <param name="initial_value">0.0</param>
      </state_interface>
      <state_interface name="effort"/>
    </joint>
    <joint name="LH_KFE">
      <command_interface name="effort"/>
      <state_interface name="position">
        <param name="initial_value">0.0</param>
      </state_interface>
      <state_interface name="velocity">
        <param name="initial_value">0.0</param>
      </state_interface>
      <state_interface name="effort"/>
    </joint>
    <joint name="LF_HAA">
      <command_interface name="effort"/>
      <state_interface name="position">
        <param name="initial_value">-0.0</param>
      </state_interface>
      <state_interface name="velocity">
        <param name="initial_value">0.0</param>
      </state_interface>
      <state_interface name="effort"/>
    </joint>
    <joint name="LF_HFE">
      <command_interface name="effort"/>
      <state_interface name="position">
        <param name="initial_value">0.0</param>
      </state_interface>
      <state_interface name="velocity">
        <param name="initial_value">0.0</param>
      </state_interface>
      <state_interface name="effort"/>
    </joint>
    <joint name="LF_KFE">
      <command_interface name="effort"/>
      <state_interface name="position">
        <param name="initial_value">0.0</param>
      </state_interface>
      <state_interface name="velocity">
        <param name="initial_value">0.0</param>
      </state_interface>
      <state_interface name="effort"/>
    </joint>
    <joint name="RH_HAA">
      <command_interface name="effort"/>
      <state_interface name="position">
        <param name="initial_value">0.0</param>
      </state_interface>
      <state_interface name="velocity">
        <param name="initial_value">0.0</param>
      </state_interface>
      <state_interface name="effort"/>
    </joint>
    <joint name="RH_HFE">
      <command_interface name="effort"/>
      <state_interface name="position">
        <param name="initial_value">0.0</param>
      </state_interface>
      <state_interface name="velocity">
        <param name="initial_value">0.0</param>
      </state_interface>
      <state_interface name="effort"/>
    </joint>
    <joint name="RH_KFE">
      <command_interface name="effort"/>
      <state_interface name="position">
        <param name="initial_value">0.0</param>
      </state_interface>
      <state_interface name="velocity">
        <param name="initial_value">0.0</param>
      </state_interface>
      <state_interface name="effort"/>
    </joint>
    <joint name="RF_HAA">
      <command_interface name="effort"/>
      <state_interface name="position">
        <param name="initial_value">0.0</param>
      </state_interface>
      <state_interface name="velocity">
        <param name="initial_value">0.0</param>
      </state_interface>
      <state_interface name="effort"/>
    </joint>
    <joint name="RF_HFE">
      <command_interface name="effort"/>
      <state_interface name="position">
        <param name="initial_value">0.0</param>
      </state_interface>
      <state_interface name="velocity">
        <param name="initial_value">0.0</param>
      </state_interface>
      <state_interface name="effort"/>
    </joint>
    <joint name="RF_KFE">
      <command_interface name="effort"/>
      <state_interface name="position">
        <param name="initial_value">0.0</param>
      </state_interface>
      <state_interface name="velocity">
        <param name="initial_value">0.0</param>
      </state_interface>
      <state_interface name="effort"/>
    </joint>
  </ros2_control>
  <gazebo reference="base_link">
    <sensor name="br_imu" type="imu">
      <always_on>true</always_on>
      <update_rate>100</update_rate>
      <imu>
        <angular_velocity>
          <x>
            <noise type="gaussian">
              <mean>0.0</mean>
              <stddev>2e-4</stddev>
            </noise>
          </x>
          <y>
            <noise type="gaussian">
              <mean>0.0</mean>
              <stddev>2e-4</stddev>
            </noise>
          </y>
          <z>
            <noise type="gaussian">
              <mean>0.0</mean>
              <stddev>2e-4</stddev>
            </noise>
          </z>
        </angular_velocity>
        <linear_acceleration>
          <x>
            <noise type="gaussian">
              <mean>0.0</mean>
              <stddev>1.7e-2</stddev>
            </noise>
          </x>
          <y>
            <noise type="gaussian">
              <mean>0.0</mean>
              <stddev>1.7e-2</stddev>
            </noise>
          </y>
          <z>
            <noise type="gaussian">
              <mean>0.0</mean>
              <stddev>1.7e-2</stddev>
            </noise>
          </z>
        </linear_acceleration>
      </imu>
      <plugin filename="libgazebo_ros_imu_sensor.so" name="bytes_imu">
        <ros>
          <namespace>imu</namespace>
          <remapping>~/out:=data</remapping>
        </ros>
        <initial_orientation_as_reference>false</initial_orientation_as_reference>
      </plugin>
    </sensor>
  </gazebo>
</robot>
