<?xml version="1.0" ?>
<!-- =================================================================================== -->
<!-- |    This document was autogenerated by xacro from solo12.urdf.xacro              | -->
<!-- |    EDITING THIS FILE BY HAND IS NOT RECOMMENDED                                 | -->
<!-- =================================================================================== -->
<robot name="solo" xmlns:controller="http://playerstage.sourceforge.net/gazebo/xmlschema/#controller" xmlns:interface="http://playerstage.sourceforge.net/gazebo/xmlschema/#interface" xmlns:sensor="http://playerstage.sourceforge.net/gazebo/xmlschema/#sensor">
  <!-- ros2_control plugin -->
  <ros2_control name="GazeboSystem" type="system">
    <hardware>
      <plugin>gazebo_ros2_control/GazeboSystem</plugin>
    </hardware>
    <joint name="LF_HAA">
      <command_interface name="effort">
        <param name="min">-20</param>
        <param name="max"> 20</param>
      </command_interface>
      <state_interface name="position"/>
      <state_interface name="velocity"/>
      <state_interface name="effort"/>
    </joint>
    <joint name="LF_HFE">
      <command_interface name="effort">
        <param name="min">-20</param>
        <param name="max"> 20</param>
      </command_interface>
      <state_interface name="position"/>
      <state_interface name="velocity"/>
      <state_interface name="effort"/>
    </joint>
    <joint name="LF_KFE">
      <command_interface name="effort">
        <param name="min">-20</param>
        <param name="max"> 20</param>
      </command_interface>
      <state_interface name="position"/>
      <state_interface name="velocity"/>
      <state_interface name="effort"/>
    </joint>
    <joint name="RF_HAA">
      <command_interface name="effort">
        <param name="min">-20</param>
        <param name="max"> 20</param>
      </command_interface>
      <state_interface name="position"/>
      <state_interface name="velocity"/>
      <state_interface name="effort"/>
    </joint>
    <joint name="RF_HFE">
      <command_interface name="effort">
        <param name="min">-20</param>
        <param name="max"> 20</param>
      </command_interface>
      <state_interface name="position"/>
      <state_interface name="velocity"/>
      <state_interface name="effort"/>
    </joint>
    <joint name="RF_KFE">
      <command_interface name="effort">
        <param name="min">-20</param>
        <param name="max"> 20</param>
      </command_interface>
      <state_interface name="position"/>
      <state_interface name="velocity"/>
      <state_interface name="effort"/>
    </joint>
    <joint name="LH_HAA">
      <command_interface name="effort">
        <param name="min">-20</param>
        <param name="max"> 20</param>
      </command_interface>
      <state_interface name="position"/>
      <state_interface name="velocity"/>
      <state_interface name="effort"/>
    </joint>
    <joint name="LH_HFE">
      <command_interface name="effort">
        <param name="min">-20</param>
        <param name="max"> 20</param>
      </command_interface>
      <state_interface name="position"/>
      <state_interface name="velocity"/>
      <state_interface name="effort"/>
    </joint>
    <joint name="LH_KFE">
      <command_interface name="effort">
        <param name="min">-20</param>
        <param name="max"> 20</param>
      </command_interface>
      <state_interface name="position"/>
      <state_interface name="velocity"/>
      <state_interface name="effort"/>
    </joint>
    <joint name="RH_HAA">
      <command_interface name="effort">
        <param name="min">-20</param>
        <param name="max"> 20</param>
      </command_interface>
      <state_interface name="position"/>
      <state_interface name="velocity"/>
      <state_interface name="effort"/>
    </joint>
    <joint name="RH_HFE">
      <command_interface name="effort">
        <param name="min">-20</param>
        <param name="max"> 20</param>
      </command_interface>
      <state_interface name="position"/>
      <state_interface name="velocity"/>
      <state_interface name="effort"/>
    </joint>
    <joint name="RH_KFE">
      <command_interface name="effort">
        <param name="min">-20</param>
        <param name="max"> 20</param>
      </command_interface>
      <state_interface name="position"/>
      <state_interface name="velocity"/>
      <state_interface name="effort"/>
    </joint>
    <sensor name="imu_sensor">
      <state_interface name="orientation.x"/>
      <state_interface name="orientation.y"/>
      <state_interface name="orientation.z"/>
      <state_interface name="orientation.w"/>
      <state_interface name="angular_velocity.x"/>
      <state_interface name="angular_velocity.y"/>
      <state_interface name="angular_velocity.z"/>
      <state_interface name="linear_acceleration.x"/>
      <state_interface name="linear_acceleration.y"/>
      <state_interface name="linear_acceleration.z"/>
    </sensor>
  </ros2_control>
  <!-- Effort_controller -->
  <gazebo>
    <plugin filename="libgazebo_ros2_control.so" name="gazebo_ros2_control">
      <parameters>/home/jacopo/Documents/control_quadrupeds_soft_contacts/install/robot_control/share/robot_control/config/gazebo/solo12_controller_effort.yaml</parameters>
    </plugin>
  </gazebo>
  <!-- IMU sensor -->
  <gazebo reference="base_link">
    <sensor name="imu_sensor" type="imu">
      <always_on>true</always_on>
      <update_rate>400</update_rate>
      <!-- <plugin name="imu_plugin" filename="libgazebo_ros_imu_sensor.so">
                <ros>
                    <namespace>/imu</namespace>
                    <remapping>~/out:=data</remapping>
                </ros>
                <frame_name>base</frame_name>
                <initial_orientation_as_reference>false</initial_orientation_as_reference>
            </plugin> -->
      <imu>
        <angular_velocity>
          <x>
            <noise type="gaussian">
              <mean>0.0</mean>
              <stddev>2e-4</stddev>
              <bias_mean>0.0000075</bias_mean>
              <bias_stddev>0.0000008</bias_stddev>
            </noise>
          </x>
          <y>
            <noise type="gaussian">
              <mean>0.0</mean>
              <stddev>2e-4</stddev>
              <bias_mean>0.0000075</bias_mean>
              <bias_stddev>0.0000008</bias_stddev>
            </noise>
          </y>
          <z>
            <noise type="gaussian">
              <mean>0.0</mean>
              <stddev>2e-4</stddev>
              <bias_mean>0.0000075</bias_mean>
              <bias_stddev>0.0000008</bias_stddev>
            </noise>
          </z>
        </angular_velocity>
        <linear_acceleration>
          <x>
            <noise type="gaussian">
              <mean>0.0</mean>
              <stddev>1.7e-2</stddev>
              <bias_mean>0.1</bias_mean>
              <bias_stddev>0.001</bias_stddev>
            </noise>
          </x>
          <y>
            <noise type="gaussian">
              <mean>0.0</mean>
              <stddev>1.7e-2</stddev>
              <bias_mean>0.1</bias_mean>
              <bias_stddev>0.001</bias_stddev>
            </noise>
          </y>
          <z>
            <noise type="gaussian">
              <mean>0.0</mean>
              <stddev>1.7e-2</stddev>
              <bias_mean>0.1</bias_mean>
              <bias_stddev>0.001</bias_stddev>
            </noise>
          </z>
        </linear_acceleration>
      </imu>
    </sensor>
  </gazebo>
  <!-- Contact sensors for the four feet -->
  <!-- LF_FOOT -->
  <gazebo reference="LF_LOWER_LEG">
    <sensor name="LF_FOOT_contct_sensor" type="contact">
      <always_on>true</always_on>
      <update_rate>25.0</update_rate>
      <contact>
        <collision>LF_LOWER_LEG_fixed_joint_lump__LF_FOOT_collision_1</collision>
      </contact>
      <plugin filename="libgazebo_ros_bumper.so" name="LF_FOOT_bumper">
        <ros>
          <!-- <namespace>demo</namespace> -->
          <remapping>bumper_states:=/contact_force_sensors/LF</remapping>
        </ros>
        <frame_name>world</frame_name>
      </plugin>
    </sensor>
  </gazebo>
  <!-- RF_FOOT -->
  <gazebo reference="RF_LOWER_LEG">
    <sensor name="RF_FOOT_contct_sensor" type="contact">
      <always_on>true</always_on>
      <update_rate>25.0</update_rate>
      <contact>
        <collision>RF_LOWER_LEG_fixed_joint_lump__RF_FOOT_collision_1</collision>
      </contact>
      <plugin filename="libgazebo_ros_bumper.so" name="RF_FOOT_bumper">
        <ros>
          <!-- <namespace>demo</namespace> -->
          <remapping>bumper_states:=/contact_force_sensors/RF</remapping>
        </ros>
        <frame_name>world</frame_name>
      </plugin>
    </sensor>
  </gazebo>
  <!-- LH_FOOT -->
  <gazebo reference="LH_LOWER_LEG">
    <sensor name="LH_FOOT_contct_sensor" type="contact">
      <always_on>true</always_on>
      <update_rate>25.0</update_rate>
      <contact>
        <collision>LH_LOWER_LEG_fixed_joint_lump__LH_FOOT_collision_1</collision>
      </contact>
      <plugin filename="libgazebo_ros_bumper.so" name="LH_FOOT_bumper">
        <ros>
          <!-- <namespace>demo</namespace> -->
          <remapping>bumper_states:=/contact_force_sensors/LH</remapping>
        </ros>
        <frame_name>world</frame_name>
      </plugin>
    </sensor>
  </gazebo>
  <!-- RH_FOOT -->
  <gazebo reference="RH_LOWER_LEG">
    <sensor name="RH_FOOT_contct_sensor" type="contact">
      <always_on>true</always_on>
      <update_rate>25.0</update_rate>
      <contact>
        <collision>RH_LOWER_LEG_fixed_joint_lump__RH_FOOT_collision_1</collision>
      </contact>
      <plugin filename="libgazebo_ros_bumper.so" name="RH_FOOT_bumper">
        <ros>
          <!-- <namespace>demo</namespace> -->
          <remapping>bumper_states:=/contact_force_sensors/RH</remapping>
        </ros>
        <frame_name>world</frame_name>
      </plugin>
    </sensor>
  </gazebo>
  <!-- This file is based on: https://atlas.is.localnet/confluence/display/AMDW/Quadruped+URDF+Files -->
  <link name="base_link">
    <!-- BASE LINK INERTIAL -->
    <inertial>
      <origin rpy="0 0 0" xyz="0 0 0"/>
      <mass value="1.16115091"/>
      <!-- The base is extremely symmetrical. -->
      <inertia ixx="0.00578574" ixy="0.0" ixz="0.0" iyy="0.01938108" iyz="0.0" izz="0.02476124"/>
    </inertial>
    <!-- BASE LINK VISUAL -->
    <visual>
      <origin rpy="0 0 0" xyz="0 0 0"/>
      <geometry>
        <mesh filename="file:///home/jacopo/Documents/control_quadrupeds_soft_contacts/install/solo_description/share/solo_description/meshes/stl/solo12/solo_12_base.stl"/>
      </geometry>
      <material name="grey">
        <color rgba="0.8 0.8 0.8 1.0"/>
      </material>
    </visual>
    <!-- BASE LINK COLLISION -->
    <collision>
      <origin rpy="0 0 0" xyz="0 0 0"/>
      <geometry>
        <mesh filename="file:///home/jacopo/Documents/control_quadrupeds_soft_contacts/install/solo_description/share/solo_description/meshes/stl/solo12/solo_12_base.stl"/>
      </geometry>
      <material name="grey">
        <color rgba="0.8 0.8 0.8 1.0"/>
      </material>
    </collision>
    <!-- Bullet specific paramters -->
    <contact>
      <lateral_friction value="1.0"/>
      <restitution value="0.5"/>
    </contact>
  </link>
  <!-- END BASE LINK -->
  <joint name="LF_HAA" type="revolute">
    <parent link="base_link"/>
    <child link="LF_SHOULDER"/>
    <limit effort="10" lower="-10" upper="10" velocity="10"/>
    <!-- joints rotates around the x-axis -->
    <axis xyz="1 0 0"/>
    <origin rpy="0 0 0" xyz="0.1946 0.08750000000000001 0"/>
    <!-- pybullet simulation parameters -->
    <dynamics damping="0.0" friction="0.0"/>
  </joint>
  <link name="LF_SHOULDER">
    <!-- TODO: Update inertias. -->
    <!-- create a dummy shoulder link to join the two joints -->
    <!-- HAA VISUAL -->
    <visual>
      <origin rpy="0 0 0" xyz="0.01950 0 0"/>
      <geometry>
        <mesh filename="file:///home/jacopo/Documents/control_quadrupeds_soft_contacts/install/solo_description/share/solo_description/meshes/stl/solo12/solo12_hip_fe_fl.stl"/>
      </geometry>
      <material name="grey">
        <color rgba="0.8 0.8 0.8 1.0"/>
      </material>
    </visual>
    <!-- HAA LINK COLLISION -->
    <collision>
      <origin rpy="0 0 0" xyz="0.01950 0 0"/>
      <geometry>
        <mesh filename="file:///home/jacopo/Documents/control_quadrupeds_soft_contacts/install/solo_description/share/solo_description/meshes/stl/solo12/solo12_hip_fe_fl.stl"/>
      </geometry>
      <material name="grey">
        <color rgba="0.8 0.8 0.8 1.0"/>
      </material>
    </collision>
    <inertial>
      <mass value="0.14853845"/>
      <!-- HAA body inertia -->
      <origin rpy="0 0 0" xyz="-0.07870700 0.01 0."/>
      <inertia ixx="0.00003024" ixy="0.00004671" ixz="0.0" iyy="0.00041193" iyz="0.0" izz="0.00041107"/>
    </inertial>
  </link>
  <joint name="LF_HFE" type="revolute">
    <parent link="LF_SHOULDER"/>
    <child link="LF_UPPER_LEG"/>
    <limit effort="10" lower="-10" upper="10" velocity="10"/>
    <!-- joints rotates around the y-axis -->
    <axis xyz="0 1 0"/>
    <origin rpy="0 0 0" xyz="0 0.014 0"/>
    <!-- pybullet simulation parameters -->
    <dynamics damping="0.0" friction="0.0"/>
  </joint>
  <link name="LF_UPPER_LEG">
    <!-- Left upper leg inertia -->
    <inertial>
      <origin rpy="0 0 0" xyz="0.00001377 0.01935853 -0.07870700"/>
      <mass value="0.14853845"/>
      <inertia ixx="0.00041107" ixy="0.0" ixz="0.0" iyy="0.00041193" iyz="0.00004671" izz="0.00003024"/>
    </inertial>
    <!-- UPPER LEG LINK VISUAL -->
    <visual>
      <origin rpy="0 0 0" xyz="0 0 0"/>
      <geometry>
        <mesh filename="file:///home/jacopo/Documents/control_quadrupeds_soft_contacts/install/solo_description/share/solo_description/meshes/stl/with_foot/solo_upper_leg_left_side.stl"/>
      </geometry>
      <material name="grey">
        <color rgba="0.8 0.8 0.8 1.0"/>
      </material>
    </visual>
    <!-- UPPER LEG LINK COLLISION -->
    <collision>
      <origin rpy="0 0 0" xyz="0 0 0"/>
      <geometry>
        <mesh filename="file:///home/jacopo/Documents/control_quadrupeds_soft_contacts/install/solo_description/share/solo_description/meshes/stl/with_foot/solo_upper_leg_left_side.stl"/>
      </geometry>
      <material name="grey">
        <color rgba="0.8 0.8 0.8 1.0"/>
      </material>
    </collision>
    <!-- Bullet specific paramters -->
    <contact>
      <lateral_friction value="1.0"/>
      <restitution value="0.5"/>
    </contact>
  </link>
  <!-- END UPPER LEG LINK -->
  <!-- KFE: Joint between the upper leg and the lower leg -->
  <joint name="LF_KFE" type="revolute">
    <parent link="LF_UPPER_LEG"/>
    <child link="LF_LOWER_LEG"/>
    <limit effort="10" lower="-10" upper="10" velocity="10"/>
    <!-- joints rotates around the y-axis -->
    <axis xyz="0 1 0"/>
    <origin rpy="0 0 0" xyz="0 0.037450000000000004 -0.16"/>
    <!-- pybullet simulation parameters -->
    <dynamics damping="0.0" friction="0.0"/>
  </joint>
  <link name="LF_LOWER_LEG">
    <!-- Left lower leg inertia -->
    <inertial>
      <origin rpy="0 0 0" xyz="0.0 0.00787644 -0.08928215"/>
      <mass value="0.03070001"/>
      <inertia ixx="0.00012024" ixy="0.0" ixz="0.0" iyy="0.00012029" iyz="0.00000305" izz="0.00000216"/>
    </inertial>
    <!-- LOWER LEG LINK VISUAL -->
    <visual>
      <origin rpy="0 0 0" xyz="0 0 0"/>
      <geometry>
        <mesh filename="file:///home/jacopo/Documents/control_quadrupeds_soft_contacts/install/solo_description/share/solo_description/meshes/stl/with_foot/solo_lower_leg_left_side.stl"/>
      </geometry>
      <material name="grey">
        <color rgba="0.8 0.8 0.8 1.0"/>
      </material>
    </visual>
    <collision>
      <origin rpy="0 0 0" xyz="0  0.0075 -0.075"/>
      <geometry>
        <box size="0.015 0.01 0.15"/>
      </geometry>
      <material name="grey">
        <color rgba="0.8 0.8 0.8 1.0"/>
      </material>
    </collision>
    <!-- Bullet specific paramters -->
    <contact>
      <lateral_friction value="1.0"/>
      <restitution value="0.5"/>
    </contact>
  </link>
  <!-- END LOWER LEG LINK -->
  <!-- KFE: Joint between the upper leg and the lower leg -->
  <joint name="LF_ANKLE" type="fixed">
    <parent link="LF_LOWER_LEG"/>
    <child link="LF_FOOT"/>
    <origin rpy="0 0 0" xyz="0 0.008 -0.16"/>
    <!-- Limits (usefull?) -->
    <limit effort="10" lower="-10" upper="10" velocity="10"/>
    <!-- pybullet simulation parameters -->
    <dynamics damping="0.0" friction="0.0"/>
  </joint>
  <link name="LF_FOOT">
    <!-- FOOT INERTIAL -->
    <!-- This link is symmetrical left or right -->
    <inertial>
      <origin rpy="0 0 0" xyz="0 0 0.00035767"/>
      <mass value="0.00693606"/>
      <inertia ixx="0.00000057" ixy="0.0" ixz="0.0" iyy="0.00000084" iyz="0.0" izz="0.00000053"/>
    </inertial>
    <!-- FOOT VISUAL -->
    <visual>
      <origin rpy="0 0 0" xyz="0 0 0"/>
      <geometry>
        <mesh filename="file:///home/jacopo/Documents/control_quadrupeds_soft_contacts/install/solo_description/share/solo_description/meshes/stl/with_foot/solo_foot.stl"/>
      </geometry>
      <material name="grey">
        <color rgba="0.8 0.8 0.8 1.0"/>
      </material>
    </visual>
    <!-- FOOT COLLISION -->
    <collision>
      <origin rpy="1.57079632679 0 0" xyz="0 0 0"/>
      <geometry>
        <sphere radius="0.015"/>
      </geometry>
      <material name="grey">
        <color rgba="0.8 0.8 0.8 1.0"/>
      </material>
    </collision>
    <!-- Bullet specific paramters -->
    <contact>
      <lateral_friction value="1.0"/>
      <restitution value="0.5"/>
    </contact>
  </link>
  <!-- END LOWER LEG LINK -->
  <gazebo reference="LF_FOOT">
    <mu1>1</mu1>
    <mu2>1</mu2>
  </gazebo>
  <joint name="RF_HAA" type="revolute">
    <parent link="base_link"/>
    <child link="RF_SHOULDER"/>
    <limit effort="10" lower="-10" upper="10" velocity="10"/>
    <!-- joints rotates around the x-axis -->
    <axis xyz="1 0 0"/>
    <origin rpy="0 0 0" xyz="0.1946 -0.08750000000000001 0"/>
    <!-- pybullet simulation parameters -->
    <dynamics damping="0.0" friction="0.0"/>
  </joint>
  <link name="RF_SHOULDER">
    <!-- TODO: Update inertias. -->
    <!-- create a dummy shoulder link to join the two joints -->
    <!-- HAA VISUAL -->
    <visual>
      <origin rpy="0 0 0" xyz="0.01950 0 0"/>
      <geometry>
        <mesh filename="file:///home/jacopo/Documents/control_quadrupeds_soft_contacts/install/solo_description/share/solo_description/meshes/stl/solo12/solo12_hip_fe_fr.stl"/>
      </geometry>
      <material name="grey">
        <color rgba="0.8 0.8 0.8 1.0"/>
      </material>
    </visual>
    <!-- HAA LINK COLLISION -->
    <collision>
      <origin rpy="0 0 0" xyz="0.01950 0 0"/>
      <geometry>
        <mesh filename="file:///home/jacopo/Documents/control_quadrupeds_soft_contacts/install/solo_description/share/solo_description/meshes/stl/solo12/solo12_hip_fe_fr.stl"/>
      </geometry>
      <material name="grey">
        <color rgba="0.8 0.8 0.8 1.0"/>
      </material>
    </collision>
    <inertial>
      <mass value="0.14853845"/>
      <!-- HAA body inertia -->
      <origin rpy="0 0 0" xyz="-0.07870700 -0.01 0."/>
      <inertia ixx="0.00003024" ixy="-0.00004671" ixz="0.0" iyy="0.00041193" iyz="0.0" izz="0.00041107"/>
    </inertial>
  </link>
  <joint name="RF_HFE" type="revolute">
    <parent link="RF_SHOULDER"/>
    <child link="RF_UPPER_LEG"/>
    <limit effort="10" lower="-10" upper="10" velocity="10"/>
    <!-- joints rotates around the y-axis -->
    <axis xyz="0 1 0"/>
    <origin rpy="0 0 0" xyz="0 -0.014 0"/>
    <!-- pybullet simulation parameters -->
    <dynamics damping="0.0" friction="0.0"/>
  </joint>
  <link name="RF_UPPER_LEG">
    <!-- Right upper leg inertia -->
    <inertial>
      <origin rpy="0 0 0" xyz="-0.00001377 -0.01935853 -0.07870700"/>
      <mass value="0.14853845"/>
      <inertia ixx="0.00041107" ixy="0.0" ixz="0.0" iyy="0.00041193" iyz="-0.00004671" izz="0.00003024"/>
    </inertial>
    <!-- UPPER LEG LINK VISUAL -->
    <visual>
      <origin rpy="0 0 0" xyz="0 0 0"/>
      <geometry>
        <mesh filename="file:///home/jacopo/Documents/control_quadrupeds_soft_contacts/install/solo_description/share/solo_description/meshes/stl/with_foot/solo_upper_leg_right_side.stl"/>
      </geometry>
      <material name="grey">
        <color rgba="0.8 0.8 0.8 1.0"/>
      </material>
    </visual>
    <!-- UPPER LEG LINK COLLISION -->
    <collision>
      <origin rpy="0 0 0" xyz="0 0 0"/>
      <geometry>
        <mesh filename="file:///home/jacopo/Documents/control_quadrupeds_soft_contacts/install/solo_description/share/solo_description/meshes/stl/with_foot/solo_upper_leg_right_side.stl"/>
      </geometry>
      <material name="grey">
        <color rgba="0.8 0.8 0.8 1.0"/>
      </material>
    </collision>
    <!-- Bullet specific paramters -->
    <contact>
      <lateral_friction value="1.0"/>
      <restitution value="0.5"/>
    </contact>
  </link>
  <!-- END UPPER LEG LINK -->
  <!-- KFE: Joint between the upper leg and the lower leg -->
  <joint name="RF_KFE" type="revolute">
    <parent link="RF_UPPER_LEG"/>
    <child link="RF_LOWER_LEG"/>
    <limit effort="10" lower="-10" upper="10" velocity="10"/>
    <!-- joints rotates around the y-axis -->
    <axis xyz="0 1 0"/>
    <origin rpy="0 0 0" xyz="0 -0.037450000000000004 -0.16"/>
    <!-- pybullet simulation parameters -->
    <dynamics damping="0.0" friction="0.0"/>
  </joint>
  <link name="RF_LOWER_LEG">
    <!-- Right lower leg inertia -->
    <inertial>
      <origin rpy="0 0 0" xyz="0.0 0.00787644 -0.08928215"/>
      <mass value="0.03070001"/>
      <inertia ixx="0.00012024" ixy="0.0" ixz="0.0" iyy="0.00012029" iyz="-0.00000305" izz="0.00000216"/>
    </inertial>
    <!-- LOWER LEG LINK VISUAL -->
    <visual>
      <origin rpy="0 0 0" xyz="0 0 0"/>
      <geometry>
        <mesh filename="file:///home/jacopo/Documents/control_quadrupeds_soft_contacts/install/solo_description/share/solo_description/meshes/stl/with_foot/solo_lower_leg_right_side.stl"/>
      </geometry>
      <material name="grey">
        <color rgba="0.8 0.8 0.8 1.0"/>
      </material>
    </visual>
    <collision>
      <origin rpy="0 0 0" xyz="0 -0.0075 -0.075"/>
      <geometry>
        <box size="0.015 0.01 0.15"/>
      </geometry>
      <material name="grey">
        <color rgba="0.8 0.8 0.8 1.0"/>
      </material>
    </collision>
    <!-- Bullet specific paramters -->
    <contact>
      <lateral_friction value="1.0"/>
      <restitution value="0.5"/>
    </contact>
  </link>
  <!-- END LOWER LEG LINK -->
  <!-- KFE: Joint between the upper leg and the lower leg -->
  <joint name="RF_ANKLE" type="fixed">
    <parent link="RF_LOWER_LEG"/>
    <child link="RF_FOOT"/>
    <origin rpy="0 0 0" xyz="0 -0.008 -0.16"/>
    <!-- Limits (usefull?) -->
    <limit effort="10" lower="-10" upper="10" velocity="10"/>
    <!-- pybullet simulation parameters -->
    <dynamics damping="0.0" friction="0.0"/>
  </joint>
  <link name="RF_FOOT">
    <!-- FOOT INERTIAL -->
    <!-- This link is symmetrical left or right -->
    <inertial>
      <origin rpy="0 0 0" xyz="0 0 0.00035767"/>
      <mass value="0.00693606"/>
      <inertia ixx="0.00000057" ixy="0.0" ixz="0.0" iyy="0.00000084" iyz="0.0" izz="0.00000053"/>
    </inertial>
    <!-- FOOT VISUAL -->
    <visual>
      <origin rpy="0 0 0" xyz="0 0 0"/>
      <geometry>
        <mesh filename="file:///home/jacopo/Documents/control_quadrupeds_soft_contacts/install/solo_description/share/solo_description/meshes/stl/with_foot/solo_foot.stl"/>
      </geometry>
      <material name="grey">
        <color rgba="0.8 0.8 0.8 1.0"/>
      </material>
    </visual>
    <!-- FOOT COLLISION -->
    <collision>
      <origin rpy="1.57079632679 0 0" xyz="0 0 0"/>
      <geometry>
        <sphere radius="0.015"/>
      </geometry>
      <material name="grey">
        <color rgba="0.8 0.8 0.8 1.0"/>
      </material>
    </collision>
    <!-- Bullet specific paramters -->
    <contact>
      <lateral_friction value="1.0"/>
      <restitution value="0.5"/>
    </contact>
  </link>
  <!-- END LOWER LEG LINK -->
  <gazebo reference="RF_FOOT">
    <mu1>1</mu1>
    <mu2>1</mu2>
  </gazebo>
  <joint name="LH_HAA" type="revolute">
    <parent link="base_link"/>
    <child link="LH_SHOULDER"/>
    <limit effort="10" lower="-10" upper="10" velocity="10"/>
    <!-- joints rotates around the x-axis -->
    <axis xyz="1 0 0"/>
    <origin rpy="0 0 0" xyz="-0.1946 0.08750000000000001 0"/>
    <!-- pybullet simulation parameters -->
    <dynamics damping="0.0" friction="0.0"/>
  </joint>
  <link name="LH_SHOULDER">
    <!-- TODO: Update inertias. -->
    <!-- create a dummy shoulder link to join the two joints -->
    <!-- HAA VISUAL -->
    <visual>
      <origin rpy="0 0 0" xyz="-0.01950 0 0"/>
      <geometry>
        <mesh filename="file:///home/jacopo/Documents/control_quadrupeds_soft_contacts/install/solo_description/share/solo_description/meshes/stl/solo12/solo12_hip_fe_hl.stl"/>
      </geometry>
      <material name="grey">
        <color rgba="0.8 0.8 0.8 1.0"/>
      </material>
    </visual>
    <!-- HAA LINK COLLISION -->
    <collision>
      <origin rpy="0 0 0" xyz="-0.01950 0 0"/>
      <geometry>
        <mesh filename="file:///home/jacopo/Documents/control_quadrupeds_soft_contacts/install/solo_description/share/solo_description/meshes/stl/solo12/solo12_hip_fe_hl.stl"/>
      </geometry>
      <material name="grey">
        <color rgba="0.8 0.8 0.8 1.0"/>
      </material>
    </collision>
    <inertial>
      <mass value="0.14853845"/>
      <!-- HAA body inertia -->
      <origin rpy="0 0 0" xyz="0.07870700 0.01 0."/>
      <inertia ixx="0.00003024" ixy="0.00004671" ixz="0.0" iyy="0.00041193" iyz="0.0" izz="0.00041107"/>
    </inertial>
  </link>
  <joint name="LH_HFE" type="revolute">
    <parent link="LH_SHOULDER"/>
    <child link="LH_UPPER_LEG"/>
    <limit effort="10" lower="-10" upper="10" velocity="10"/>
    <!-- joints rotates around the y-axis -->
    <axis xyz="0 1 0"/>
    <origin rpy="0 0 0" xyz="0 0.014 0"/>
    <!-- pybullet simulation parameters -->
    <dynamics damping="0.0" friction="0.0"/>
  </joint>
  <link name="LH_UPPER_LEG">
    <!-- Left upper leg inertia -->
    <inertial>
      <origin rpy="0 0 0" xyz="0.00001377 0.01935853 -0.07870700"/>
      <mass value="0.14853845"/>
      <inertia ixx="0.00041107" ixy="0.0" ixz="0.0" iyy="0.00041193" iyz="0.00004671" izz="0.00003024"/>
    </inertial>
    <!-- UPPER LEG LINK VISUAL -->
    <visual>
      <origin rpy="0 0 0" xyz="0 0 0"/>
      <geometry>
        <mesh filename="file:///home/jacopo/Documents/control_quadrupeds_soft_contacts/install/solo_description/share/solo_description/meshes/stl/with_foot/solo_upper_leg_left_side.stl"/>
      </geometry>
      <material name="grey">
        <color rgba="0.8 0.8 0.8 1.0"/>
      </material>
    </visual>
    <!-- UPPER LEG LINK COLLISION -->
    <collision>
      <origin rpy="0 0 0" xyz="0 0 0"/>
      <geometry>
        <mesh filename="file:///home/jacopo/Documents/control_quadrupeds_soft_contacts/install/solo_description/share/solo_description/meshes/stl/with_foot/solo_upper_leg_left_side.stl"/>
      </geometry>
      <material name="grey">
        <color rgba="0.8 0.8 0.8 1.0"/>
      </material>
    </collision>
    <!-- Bullet specific paramters -->
    <contact>
      <lateral_friction value="1.0"/>
      <restitution value="0.5"/>
    </contact>
  </link>
  <!-- END UPPER LEG LINK -->
  <!-- KFE: Joint between the upper leg and the lower leg -->
  <joint name="LH_KFE" type="revolute">
    <parent link="LH_UPPER_LEG"/>
    <child link="LH_LOWER_LEG"/>
    <limit effort="10" lower="-10" upper="10" velocity="10"/>
    <!-- joints rotates around the y-axis -->
    <axis xyz="0 1 0"/>
    <origin rpy="0 0 0" xyz="0 0.037450000000000004 -0.16"/>
    <!-- pybullet simulation parameters -->
    <dynamics damping="0.0" friction="0.0"/>
  </joint>
  <link name="LH_LOWER_LEG">
    <!-- Left lower leg inertia -->
    <inertial>
      <origin rpy="0 0 0" xyz="0.0 0.00787644 -0.08928215"/>
      <mass value="0.03070001"/>
      <inertia ixx="0.00012024" ixy="0.0" ixz="0.0" iyy="0.00012029" iyz="0.00000305" izz="0.00000216"/>
    </inertial>
    <!-- LOWER LEG LINK VISUAL -->
    <visual>
      <origin rpy="0 0 0" xyz="0 0 0"/>
      <geometry>
        <mesh filename="file:///home/jacopo/Documents/control_quadrupeds_soft_contacts/install/solo_description/share/solo_description/meshes/stl/with_foot/solo_lower_leg_left_side.stl"/>
      </geometry>
      <material name="grey">
        <color rgba="0.8 0.8 0.8 1.0"/>
      </material>
    </visual>
    <collision>
      <origin rpy="0 0 0" xyz="0  0.0075 -0.075"/>
      <geometry>
        <box size="0.015 0.01 0.15"/>
      </geometry>
      <material name="grey">
        <color rgba="0.8 0.8 0.8 1.0"/>
      </material>
    </collision>
    <!-- Bullet specific paramters -->
    <contact>
      <lateral_friction value="1.0"/>
      <restitution value="0.5"/>
    </contact>
  </link>
  <!-- END LOWER LEG LINK -->
  <!-- KFE: Joint between the upper leg and the lower leg -->
  <joint name="LH_ANKLE" type="fixed">
    <parent link="LH_LOWER_LEG"/>
    <child link="LH_FOOT"/>
    <origin rpy="0 0 0" xyz="0 0.008 -0.16"/>
    <!-- Limits (usefull?) -->
    <limit effort="10" lower="-10" upper="10" velocity="10"/>
    <!-- pybullet simulation parameters -->
    <dynamics damping="0.0" friction="0.0"/>
  </joint>
  <link name="LH_FOOT">
    <!-- FOOT INERTIAL -->
    <!-- This link is symmetrical left or right -->
    <inertial>
      <origin rpy="0 0 0" xyz="0 0 0.00035767"/>
      <mass value="0.00693606"/>
      <inertia ixx="0.00000057" ixy="0.0" ixz="0.0" iyy="0.00000084" iyz="0.0" izz="0.00000053"/>
    </inertial>
    <!-- FOOT VISUAL -->
    <visual>
      <origin rpy="0 0 0" xyz="0 0 0"/>
      <geometry>
        <mesh filename="file:///home/jacopo/Documents/control_quadrupeds_soft_contacts/install/solo_description/share/solo_description/meshes/stl/with_foot/solo_foot.stl"/>
      </geometry>
      <material name="grey">
        <color rgba="0.8 0.8 0.8 1.0"/>
      </material>
    </visual>
    <!-- FOOT COLLISION -->
    <collision>
      <origin rpy="1.57079632679 0 0" xyz="0 0 0"/>
      <geometry>
        <sphere radius="0.015"/>
      </geometry>
      <material name="grey">
        <color rgba="0.8 0.8 0.8 1.0"/>
      </material>
    </collision>
    <!-- Bullet specific paramters -->
    <contact>
      <lateral_friction value="1.0"/>
      <restitution value="0.5"/>
    </contact>
  </link>
  <!-- END LOWER LEG LINK -->
  <gazebo reference="LH_FOOT">
    <mu1>1</mu1>
    <mu2>1</mu2>
  </gazebo>
  <joint name="RH_HAA" type="revolute">
    <parent link="base_link"/>
    <child link="RH_SHOULDER"/>
    <limit effort="10" lower="-10" upper="10" velocity="10"/>
    <!-- joints rotates around the x-axis -->
    <axis xyz="1 0 0"/>
    <origin rpy="0 0 0" xyz="-0.1946 -0.08750000000000001 0"/>
    <!-- pybullet simulation parameters -->
    <dynamics damping="0.0" friction="0.0"/>
  </joint>
  <link name="RH_SHOULDER">
    <!-- TODO: Update inertias. -->
    <!-- create a dummy shoulder link to join the two joints -->
    <!-- HAA VISUAL -->
    <visual>
      <origin rpy="0 0 0" xyz="-0.01950 0 0"/>
      <geometry>
        <mesh filename="file:///home/jacopo/Documents/control_quadrupeds_soft_contacts/install/solo_description/share/solo_description/meshes/stl/solo12/solo12_hip_fe_hr.stl"/>
      </geometry>
      <material name="grey">
        <color rgba="0.8 0.8 0.8 1.0"/>
      </material>
    </visual>
    <!-- HAA LINK COLLISION -->
    <collision>
      <origin rpy="0 0 0" xyz="-0.01950 0 0"/>
      <geometry>
        <mesh filename="file:///home/jacopo/Documents/control_quadrupeds_soft_contacts/install/solo_description/share/solo_description/meshes/stl/solo12/solo12_hip_fe_hr.stl"/>
      </geometry>
      <material name="grey">
        <color rgba="0.8 0.8 0.8 1.0"/>
      </material>
    </collision>
    <inertial>
      <mass value="0.14853845"/>
      <!-- HAA body inertia -->
      <origin rpy="0 0 0" xyz="0.07870700 -0.01 0."/>
      <inertia ixx="0.00003024" ixy="-0.00004671" ixz="0.0" iyy="0.00041193" iyz="0.0" izz="0.00041107"/>
    </inertial>
  </link>
  <joint name="RH_HFE" type="revolute">
    <parent link="RH_SHOULDER"/>
    <child link="RH_UPPER_LEG"/>
    <limit effort="10" lower="-10" upper="10" velocity="10"/>
    <!-- joints rotates around the y-axis -->
    <axis xyz="0 1 0"/>
    <origin rpy="0 0 0" xyz="0 -0.014 0"/>
    <!-- pybullet simulation parameters -->
    <dynamics damping="0.0" friction="0.0"/>
  </joint>
  <link name="RH_UPPER_LEG">
    <!-- Right upper leg inertia -->
    <inertial>
      <origin rpy="0 0 0" xyz="-0.00001377 -0.01935853 -0.07870700"/>
      <mass value="0.14853845"/>
      <inertia ixx="0.00041107" ixy="0.0" ixz="0.0" iyy="0.00041193" iyz="-0.00004671" izz="0.00003024"/>
    </inertial>
    <!-- UPPER LEG LINK VISUAL -->
    <visual>
      <origin rpy="0 0 0" xyz="0 0 0"/>
      <geometry>
        <mesh filename="file:///home/jacopo/Documents/control_quadrupeds_soft_contacts/install/solo_description/share/solo_description/meshes/stl/with_foot/solo_upper_leg_right_side.stl"/>
      </geometry>
      <material name="grey">
        <color rgba="0.8 0.8 0.8 1.0"/>
      </material>
    </visual>
    <!-- UPPER LEG LINK COLLISION -->
    <collision>
      <origin rpy="0 0 0" xyz="0 0 0"/>
      <geometry>
        <mesh filename="file:///home/jacopo/Documents/control_quadrupeds_soft_contacts/install/solo_description/share/solo_description/meshes/stl/with_foot/solo_upper_leg_right_side.stl"/>
      </geometry>
      <material name="grey">
        <color rgba="0.8 0.8 0.8 1.0"/>
      </material>
    </collision>
    <!-- Bullet specific paramters -->
    <contact>
      <lateral_friction value="1.0"/>
      <restitution value="0.5"/>
    </contact>
  </link>
  <!-- END UPPER LEG LINK -->
  <!-- KFE: Joint between the upper leg and the lower leg -->
  <joint name="RH_KFE" type="revolute">
    <parent link="RH_UPPER_LEG"/>
    <child link="RH_LOWER_LEG"/>
    <limit effort="10" lower="-10" upper="10" velocity="10"/>
    <!-- joints rotates around the y-axis -->
    <axis xyz="0 1 0"/>
    <origin rpy="0 0 0" xyz="0 -0.037450000000000004 -0.16"/>
    <!-- pybullet simulation parameters -->
    <dynamics damping="0.0" friction="0.0"/>
  </joint>
  <link name="RH_LOWER_LEG">
    <!-- Right lower leg inertia -->
    <inertial>
      <origin rpy="0 0 0" xyz="0.0 0.00787644 -0.08928215"/>
      <mass value="0.03070001"/>
      <inertia ixx="0.00012024" ixy="0.0" ixz="0.0" iyy="0.00012029" iyz="-0.00000305" izz="0.00000216"/>
    </inertial>
    <!-- LOWER LEG LINK VISUAL -->
    <visual>
      <origin rpy="0 0 0" xyz="0 0 0"/>
      <geometry>
        <mesh filename="file:///home/jacopo/Documents/control_quadrupeds_soft_contacts/install/solo_description/share/solo_description/meshes/stl/with_foot/solo_lower_leg_right_side.stl"/>
      </geometry>
      <material name="grey">
        <color rgba="0.8 0.8 0.8 1.0"/>
      </material>
    </visual>
    <collision>
      <origin rpy="0 0 0" xyz="0 -0.0075 -0.075"/>
      <geometry>
        <box size="0.015 0.01 0.15"/>
      </geometry>
      <material name="grey">
        <color rgba="0.8 0.8 0.8 1.0"/>
      </material>
    </collision>
    <!-- Bullet specific paramters -->
    <contact>
      <lateral_friction value="1.0"/>
      <restitution value="0.5"/>
    </contact>
  </link>
  <!-- END LOWER LEG LINK -->
  <!-- KFE: Joint between the upper leg and the lower leg -->
  <joint name="RH_ANKLE" type="fixed">
    <parent link="RH_LOWER_LEG"/>
    <child link="RH_FOOT"/>
    <origin rpy="0 0 0" xyz="0 -0.008 -0.16"/>
    <!-- Limits (usefull?) -->
    <limit effort="10" lower="-10" upper="10" velocity="10"/>
    <!-- pybullet simulation parameters -->
    <dynamics damping="0.0" friction="0.0"/>
  </joint>
  <link name="RH_FOOT">
    <!-- FOOT INERTIAL -->
    <!-- This link is symmetrical left or right -->
    <inertial>
      <origin rpy="0 0 0" xyz="0 0 0.00035767"/>
      <mass value="0.00693606"/>
      <inertia ixx="0.00000057" ixy="0.0" ixz="0.0" iyy="0.00000084" iyz="0.0" izz="0.00000053"/>
    </inertial>
    <!-- FOOT VISUAL -->
    <visual>
      <origin rpy="0 0 0" xyz="0 0 0"/>
      <geometry>
        <mesh filename="file:///home/jacopo/Documents/control_quadrupeds_soft_contacts/install/solo_description/share/solo_description/meshes/stl/with_foot/solo_foot.stl"/>
      </geometry>
      <material name="grey">
        <color rgba="0.8 0.8 0.8 1.0"/>
      </material>
    </visual>
    <!-- FOOT COLLISION -->
    <collision>
      <origin rpy="1.57079632679 0 0" xyz="0 0 0"/>
      <geometry>
        <sphere radius="0.015"/>
      </geometry>
      <material name="grey">
        <color rgba="0.8 0.8 0.8 1.0"/>
      </material>
    </collision>
    <!-- Bullet specific paramters -->
    <contact>
      <lateral_friction value="1.0"/>
      <restitution value="0.5"/>
    </contact>
  </link>
  <!-- END LOWER LEG LINK -->
  <gazebo reference="RH_FOOT">
    <mu1>1</mu1>
    <mu2>1</mu2>
  </gazebo>
</robot>
