<?xml version="1.0" ?>
<!-- =================================================================================== -->
<!-- |    This document was autogenerated by xacro from src/solo_robot_description/urdf/again/solo12.urdf.xacro | -->
<!-- |    EDITING THIS FILE BY HAND IS NOT RECOMMENDED                                 | -->
<!-- =================================================================================== -->
<robot name="solo">
  <!--<xacro:property name="solo_foot" 
    value="file://$(find solo_robot_description)/meshes/stl//with_foot/solo_foot.${mesh_ext}"/>-->
  <!--<xacro:property name="solo_foot" 
    value="file://$(find solo_robot_description)/meshes/stl//with_foot/solo_foot.${mesh_ext}"/>-->
  <material name="black">
    <color rgba="0.0 0.0 0.0 1.0"/>
  </material>
  <material name="blue">
    <color rgba="0.0 0.0 0.8 1.0"/>
  </material>
  <material name="green">
    <color rgba="0.0 0.8 0.0 1.0"/>
  </material>
  <material name="grey">
    <color rgba="0.2 0.2 0.2 1.0"/>
  </material>
  <material name="orange">
    <color rgba="1.0 0.4235294117647059 0.0392156862745098 0.5"/>
  </material>
  <material name="brown">
    <color rgba="0.8705882352941177 0.8117647058823529 0.7647058823529411 1.0"/>
  </material>
  <material name="red">
    <color rgba="0.8 0.0 0.0 1.0"/>
  </material>
  <material name="white">
    <color rgba="1.0 1.0 1.0 0.7"/>
  </material>
  <link name="base_link">
    <visual>
      <material name="white"/>
      <origin rpy="0 0 0" xyz="0 0 0"/>
      <geometry>
        <mesh filename="file:///home/jacopo/Documents/mul_pronto_ws/install/solo_robot_description/share/solo_robot_description/urdf/meshes/stl/solo12/solo_12_base.stl"/>
      </geometry>
    </visual>
    <collision>
      <origin rpy="0 0 0" xyz="0 0 0"/>
      <geometry>
        <mesh filename="file:///home/jacopo/Documents/mul_pronto_ws/install/solo_robot_description/share/solo_robot_description/urdf/meshes/stl/solo12/solo_12_base.stl"/>
      </geometry>
    </collision>
    <inertial>
      <origin rpy="0 0 0" xyz="0 0 0"/>
      <mass value="1.16115091"/>
      <inertia ixx="0.00578574" ixy="0.0" ixz="0.0" iyy="0.01938108" iyz="0.0" izz="0.02476124"/>
    </inertial>
  </link>
  <!--<joint name="{prefix}_HAA_DEBUG" type="fixed">
            <parent name="base_link"/>
            <child name="${prefix}_SHOULDER_DEGUB"/>
            <origin xyz="${base_to_hip_xyz}" rpy="0 0 0"/>
        </joint>

        <link name="${prefix}_SHOULDER_DEBUG" />-->
  <joint name="LF_HAA" type="revolute">
    <parent link="base_link"/>
    <child link="LF_SHOULDER"/>
    <origin rpy="0 0 0" xyz="0.1946 0.08750000000000001 0"/>
    <axis xyz="1 0 0"/>
    <limit effort="25" lower="-3.141592" upper="3.141592" velocity="1.5"/>
    <dynamics damping="0.7" friction="100.0"/>
  </joint>
  <link name="LF_SHOULDER">
    <visual>
      <material name="white"/>
      <origin rpy="0 0 0" xyz="0.01950 0 0"/>
      <geometry>
        <mesh filename="file:///home/jacopo/Documents/mul_pronto_ws/install/solo_robot_description/share/solo_robot_description/urdf/meshes/stl/solo12/solo12_hip_fe_fl.stl"/>
      </geometry>
    </visual>
    <collision>
      <origin rpy="0 0 0" xyz="0.01950 0 0"/>
      <geometry>
        <mesh filename="file:///home/jacopo/Documents/mul_pronto_ws/install/solo_robot_description/share/solo_robot_description/urdf/meshes/stl/solo12/solo12_hip_fe_fl.stl"/>
      </geometry>
    </collision>
    <inertial>
      <mass value="0.14853845"/>
      <origin rpy="0 0 0" xyz="-0.07870700 0.01 0."/>
      <inertia ixx="0.00003024" ixy="0.00004671" ixz="0.0" iyy="0.00041193" iyz="0.0" izz="0.00041107"/>
    </inertial>
  </link>
  <joint name="LF_HFE" type="revolute">
    <parent link="LF_SHOULDER"/>
    <child link="LF_UPPER_LEG"/>
    <origin rpy="0 0 0" xyz="0 0.014 0"/>
    <axis xyz="0 1 0"/>
    <limit effort="25" lower="-3.141592" upper="3.141592" velocity="1.5"/>
    <dynamics damping="0.7" friction="100.0"/>
  </joint>
  <link name="LF_UPPER_LEG">
    <visual>
      <material name="white"/>
      <origin rpy="0 0 0" xyz="0 0 0"/>
      <geometry>
        <mesh filename="file:///home/jacopo/Documents/mul_pronto_ws/install/solo_robot_description/share/solo_robot_description/urdf/meshes/stl/solo12/solo12_upper_leg_left_side.stl"/>
      </geometry>
    </visual>
    <collision>
      <origin rpy="0 0 0" xyz="0 0 0"/>
      <geometry>
        <mesh filename="file:///home/jacopo/Documents/mul_pronto_ws/install/solo_robot_description/share/solo_robot_description/urdf/meshes/stl/solo12/solo12_upper_leg_left_side.stl"/>
      </geometry>
    </collision>
    <inertial>
      <mass value="0.14853845"/>
      <origin rpy="0 0 0" xyz="0.00001377 0.01935853 -0.07870700"/>
      <inertia ixx="0.00041107" ixy="0.0" ixz="0.0" iyy="0.00041193" iyz="0.00004671" izz="0.00003024"/>
    </inertial>
  </link>
  <joint name="LF_KFE" type="revolute">
    <parent link="LF_UPPER_LEG"/>
    <child link="LF_LOWER_LEG"/>
    <origin rpy="0 0 0" xyz="0 0.037450000000000004 -0.16"/>
    <axis xyz="0 1 0"/>
    <limit effort="25" lower="-3.141592" upper="3.141592" velocity="1.5"/>
    <dynamics damping="0.7" friction="100.0"/>
  </joint>
  <link name="LF_LOWER_LEG">
    <visual>
      <material name="white"/>
      <origin rpy="0 0 0" xyz="0 0 0"/>
      <geometry>
        <mesh filename="file:///home/jacopo/Documents/mul_pronto_ws/install/solo_robot_description/share/solo_robot_description/urdf/meshes/stl/solo12/solo12_lower_leg_left_side.stl"/>
      </geometry>
    </visual>
    <collision name="LF_LOWER_LEG">
      <origin rpy="0 0 0" xyz="0 0 0"/>
      <geometry>
        <mesh filename="file:///home/jacopo/Documents/mul_pronto_ws/install/solo_robot_description/share/solo_robot_description/urdf/meshes/stl/solo12/solo12_lower_leg_left_side.stl"/>
      </geometry>
    </collision>
    <inertial>
      <mass value="0.03070001"/>
      <origin rpy="0 0 0" xyz="0.0 0.00787644 -0.08928215"/>
      <inertia ixx="0.00012024" ixy="0.0" ixz="0.0" iyy="0.00012029" iyz="0.00000305" izz="0.00000216"/>
    </inertial>
  </link>
  <!--<joint name="${prefix}_ANKLE" type="fixed">
            <parent link="${prefix}_LOWER_LEG"/>
            <child link="${prefix}_FOOT"/>
           
           <xacro:if value="${prefix == 'LF'}">
                <origin xyz="0 ${KFE_2_FOOT_y} ${-KFE_2_FOOT_z}" rpy="0 0 0" />
            </xacro:if>
            <xacro:if value="${prefix == 'LH'}">
                <origin xyz="0 ${KFE_2_FOOT_y} ${-KFE_2_FOOT_z}" rpy="0 0 0" />
            </xacro:if>
            <xacro:if value="${prefix == 'RF'}">
                <origin xyz="0 ${-KFE_2_FOOT_y} ${-KFE_2_FOOT_z}" rpy="0 0 0" />
            </xacro:if>
            <xacro:if value="${prefix == 'RH'}">
                <origin xyz="0 ${-KFE_2_FOOT_y} ${-KFE_2_FOOT_z}" rpy="0 0 0" />
            </xacro:if>


        </joint>
        
        <link name="${prefix}_FOOT">
            <inertial>
                <origin xyz="0 0 0.00035767" rpy="0 0 0" />
                <mass value="0.00693606"/>
                <inertia ixx="0.00000057" ixy="0.0"         ixz="0.0"
                                        iyy="0.00000084" iyz="0.0"
                                                            izz="0.00000053"/>
            </inertial>
            <visual>
                <origin xyz="0 0 0" rpy="0 0 0" />
                <mesh filename="${solo_foot}"/>
            </visual>
            <collision>
                <origin xyz="0 0 0" rpy="0 0 0" />
                <mesh filename="${solo_foot}"/>
            </collision>
        </link>
        <gazebo reference="${prefix}_FOOT">
            <material>Gazebo/Black</material>
            <collision>
                <surface>
                    <friction>
                        <ode>
                            <mu>100</mu>
                            <mu2>100</mu2>
                            <slip1>0</slip1>
                            <slip2>0</slip2>
                        </ode>
                    </friction>
                    <contact>
                        <ode>
                            <kp>1000000.0</kp>
                            <kd>100.0</kd>
                            <min_depth>0.001</min_depth>
                        </ode>
                    </contact>
                </surface>
            </collision>
        </gazebo>-->
  <!--<joint name="{prefix}_HAA_DEBUG" type="fixed">
            <parent name="base_link"/>
            <child name="${prefix}_SHOULDER_DEGUB"/>
            <origin xyz="${base_to_hip_xyz}" rpy="0 0 0"/>
        </joint>

        <link name="${prefix}_SHOULDER_DEBUG" />-->
  <joint name="LH_HAA" type="revolute">
    <parent link="base_link"/>
    <child link="LH_SHOULDER"/>
    <origin rpy="0 0 0" xyz="-0.1946 0.08750000000000001 0"/>
    <axis xyz="1 0 0"/>
    <limit effort="25" lower="-3.141592" upper="3.141592" velocity="1.5"/>
    <dynamics damping="0.7" friction="100.0"/>
  </joint>
  <link name="LH_SHOULDER">
    <visual>
      <material name="white"/>
      <origin rpy="0 0 0" xyz="-0.01950 0 0"/>
      <geometry>
        <mesh filename="file:///home/jacopo/Documents/mul_pronto_ws/install/solo_robot_description/share/solo_robot_description/urdf/meshes/stl/solo12/solo12_hip_fe_hl.stl"/>
      </geometry>
    </visual>
    <collision>
      <origin rpy="0 0 0" xyz="-0.01950 0 0"/>
      <geometry>
        <mesh filename="file:///home/jacopo/Documents/mul_pronto_ws/install/solo_robot_description/share/solo_robot_description/urdf/meshes/stl/solo12/solo12_hip_fe_hl.stl"/>
      </geometry>
    </collision>
    <inertial>
      <mass value="0.14853845"/>
      <origin rpy="0 0 0" xyz="0.07870700 0.01 0."/>
      <inertia ixx="0.00003024" ixy="0.00004671" ixz="0.0" iyy="0.00041193" iyz="0.0" izz="0.00041107"/>
    </inertial>
  </link>
  <joint name="LH_HFE" type="revolute">
    <parent link="LH_SHOULDER"/>
    <child link="LH_UPPER_LEG"/>
    <origin rpy="0 0 0" xyz="0 0.014 0"/>
    <axis xyz="0 1 0"/>
    <limit effort="25" lower="-3.141592" upper="3.141592" velocity="1.5"/>
    <dynamics damping="0.7" friction="100.0"/>
  </joint>
  <link name="LH_UPPER_LEG">
    <visual>
      <material name="white"/>
      <origin rpy="0 0 0" xyz="0 0 0"/>
      <geometry>
        <mesh filename="file:///home/jacopo/Documents/mul_pronto_ws/install/solo_robot_description/share/solo_robot_description/urdf/meshes/stl/solo12/solo12_upper_leg_left_side.stl"/>
      </geometry>
    </visual>
    <collision>
      <origin rpy="0 0 0" xyz="0 0 0"/>
      <geometry>
        <mesh filename="file:///home/jacopo/Documents/mul_pronto_ws/install/solo_robot_description/share/solo_robot_description/urdf/meshes/stl/solo12/solo12_upper_leg_left_side.stl"/>
      </geometry>
    </collision>
    <inertial>
      <mass value="0.14853845"/>
      <origin rpy="0 0 0" xyz="0.00001377 0.01935853 -0.07870700"/>
      <inertia ixx="0.00041107" ixy="0.0" ixz="0.0" iyy="0.00041193" iyz="0.00004671" izz="0.00003024"/>
    </inertial>
  </link>
  <joint name="LH_KFE" type="revolute">
    <parent link="LH_UPPER_LEG"/>
    <child link="LH_LOWER_LEG"/>
    <origin rpy="0 0 0" xyz="0 0.037450000000000004 -0.16"/>
    <axis xyz="0 1 0"/>
    <limit effort="25" lower="-3.141592" upper="3.141592" velocity="1.5"/>
    <dynamics damping="0.7" friction="100.0"/>
  </joint>
  <link name="LH_LOWER_LEG">
    <visual>
      <material name="white"/>
      <origin rpy="0 0 0" xyz="0 0 0"/>
      <geometry>
        <mesh filename="file:///home/jacopo/Documents/mul_pronto_ws/install/solo_robot_description/share/solo_robot_description/urdf/meshes/stl/solo12/solo12_lower_leg_left_side.stl"/>
      </geometry>
    </visual>
    <collision name="LH_LOWER_LEG">
      <origin rpy="0 0 0" xyz="0 0 0"/>
      <geometry>
        <mesh filename="file:///home/jacopo/Documents/mul_pronto_ws/install/solo_robot_description/share/solo_robot_description/urdf/meshes/stl/solo12/solo12_lower_leg_left_side.stl"/>
      </geometry>
    </collision>
    <inertial>
      <mass value="0.03070001"/>
      <origin rpy="0 0 0" xyz="0.0 0.00787644 -0.08928215"/>
      <inertia ixx="0.00012024" ixy="0.0" ixz="0.0" iyy="0.00012029" iyz="0.00000305" izz="0.00000216"/>
    </inertial>
  </link>
  <!--<joint name="${prefix}_ANKLE" type="fixed">
            <parent link="${prefix}_LOWER_LEG"/>
            <child link="${prefix}_FOOT"/>
           
           <xacro:if value="${prefix == 'LF'}">
                <origin xyz="0 ${KFE_2_FOOT_y} ${-KFE_2_FOOT_z}" rpy="0 0 0" />
            </xacro:if>
            <xacro:if value="${prefix == 'LH'}">
                <origin xyz="0 ${KFE_2_FOOT_y} ${-KFE_2_FOOT_z}" rpy="0 0 0" />
            </xacro:if>
            <xacro:if value="${prefix == 'RF'}">
                <origin xyz="0 ${-KFE_2_FOOT_y} ${-KFE_2_FOOT_z}" rpy="0 0 0" />
            </xacro:if>
            <xacro:if value="${prefix == 'RH'}">
                <origin xyz="0 ${-KFE_2_FOOT_y} ${-KFE_2_FOOT_z}" rpy="0 0 0" />
            </xacro:if>


        </joint>
        
        <link name="${prefix}_FOOT">
            <inertial>
                <origin xyz="0 0 0.00035767" rpy="0 0 0" />
                <mass value="0.00693606"/>
                <inertia ixx="0.00000057" ixy="0.0"         ixz="0.0"
                                        iyy="0.00000084" iyz="0.0"
                                                            izz="0.00000053"/>
            </inertial>
            <visual>
                <origin xyz="0 0 0" rpy="0 0 0" />
                <mesh filename="${solo_foot}"/>
            </visual>
            <collision>
                <origin xyz="0 0 0" rpy="0 0 0" />
                <mesh filename="${solo_foot}"/>
            </collision>
        </link>
        <gazebo reference="${prefix}_FOOT">
            <material>Gazebo/Black</material>
            <collision>
                <surface>
                    <friction>
                        <ode>
                            <mu>100</mu>
                            <mu2>100</mu2>
                            <slip1>0</slip1>
                            <slip2>0</slip2>
                        </ode>
                    </friction>
                    <contact>
                        <ode>
                            <kp>1000000.0</kp>
                            <kd>100.0</kd>
                            <min_depth>0.001</min_depth>
                        </ode>
                    </contact>
                </surface>
            </collision>
        </gazebo>-->
  <!--<joint name="{prefix}_HAA_DEBUG" type="fixed">
            <parent name="base_link"/>
            <child name="${prefix}_SHOULDER_DEGUB"/>
            <origin xyz="${base_to_hip_xyz}" rpy="0 0 0"/>
        </joint>

        <link name="${prefix}_SHOULDER_DEBUG" />-->
  <joint name="RF_HAA" type="revolute">
    <parent link="base_link"/>
    <child link="RF_SHOULDER"/>
    <origin rpy="0 0 0" xyz="0.1946 -0.08750000000000001 0"/>
    <axis xyz="1 0 0"/>
    <limit effort="25" lower="-3.141592" upper="3.141592" velocity="1.5"/>
    <dynamics damping="0.7" friction="100.0"/>
  </joint>
  <link name="RF_SHOULDER">
    <visual>
      <material name="white"/>
      <origin rpy="0 0 0" xyz="0.01950 0 0"/>
      <geometry>
        <mesh filename="file:///home/jacopo/Documents/mul_pronto_ws/install/solo_robot_description/share/solo_robot_description/urdf/meshes/stl/solo12/solo12_hip_fe_fr.stl"/>
      </geometry>
    </visual>
    <collision>
      <origin rpy="0 0 0" xyz="0.01950 0 0"/>
      <geometry>
        <mesh filename="file:///home/jacopo/Documents/mul_pronto_ws/install/solo_robot_description/share/solo_robot_description/urdf/meshes/stl/solo12/solo12_hip_fe_fr.stl"/>
      </geometry>
    </collision>
    <inertial>
      <mass value="0.14853845"/>
      <origin rpy="0 0 0" xyz="-0.07870700 -0.01 0."/>
      <inertia ixx="0.00003024" ixy="-0.00004671" ixz="0.0" iyy="0.00041193" iyz="0.0" izz="0.00041107"/>
    </inertial>
  </link>
  <joint name="RF_HFE" type="revolute">
    <parent link="RF_SHOULDER"/>
    <child link="RF_UPPER_LEG"/>
    <origin rpy="0 0 0" xyz="0 -0.014 0"/>
    <axis xyz="0 1 0"/>
    <limit effort="25" lower="-3.141592" upper="3.141592" velocity="1.5"/>
    <dynamics damping="0.7" friction="100.0"/>
  </joint>
  <link name="RF_UPPER_LEG">
    <visual>
      <material name="white"/>
      <origin rpy="0 0 0" xyz="0 0 0"/>
      <geometry>
        <mesh filename="file:///home/jacopo/Documents/mul_pronto_ws/install/solo_robot_description/share/solo_robot_description/urdf/meshes/stl/solo12/solo12_upper_leg_right_side.stl"/>
      </geometry>
    </visual>
    <collision>
      <origin rpy="0 0 0" xyz="0 0 0"/>
      <geometry>
        <mesh filename="file:///home/jacopo/Documents/mul_pronto_ws/install/solo_robot_description/share/solo_robot_description/urdf/meshes/stl/solo12/solo12_upper_leg_right_side.stl"/>
      </geometry>
    </collision>
    <inertial>
      <mass value="0.14853845"/>
      <origin rpy="0 0 0" xyz="-0.00001377 -0.01935853 -0.07870700"/>
      <inertia ixx="0.00041107" ixy="0.0" ixz="0.0" iyy="0.00041193" iyz="-0.00004671" izz="0.00003024"/>
    </inertial>
  </link>
  <joint name="RF_KFE" type="revolute">
    <parent link="RF_UPPER_LEG"/>
    <child link="RF_LOWER_LEG"/>
    <origin rpy="0 0 0" xyz="0 -0.037450000000000004 -0.16"/>
    <axis xyz="0 1 0"/>
    <limit effort="25" lower="-3.141592" upper="3.141592" velocity="1.5"/>
    <dynamics damping="0.7" friction="100.0"/>
  </joint>
  <link name="RF_LOWER_LEG">
    <visual>
      <material name="white"/>
      <origin rpy="0 0 0" xyz="0 0 0"/>
      <geometry>
        <mesh filename="file:///home/jacopo/Documents/mul_pronto_ws/install/solo_robot_description/share/solo_robot_description/urdf/meshes/stl/solo12/solo12_lower_leg_right_side.stl"/>
      </geometry>
    </visual>
    <collision name="RF_LOWER_LEG">
      <origin rpy="0 0 0" xyz="0 0 0"/>
      <geometry>
        <mesh filename="file:///home/jacopo/Documents/mul_pronto_ws/install/solo_robot_description/share/solo_robot_description/urdf/meshes/stl/solo12/solo12_lower_leg_right_side.stl"/>
      </geometry>
    </collision>
    <inertial>
      <mass value="0.03070001"/>
      <origin rpy="0 0 0" xyz="0.0 0.00787644 -0.08928215"/>
      <inertia ixx="0.00012024" ixy="0.0" ixz="0.0" iyy="0.00012029" iyz="-0.00000305" izz="0.00000216"/>
    </inertial>
  </link>
  <!--<joint name="${prefix}_ANKLE" type="fixed">
            <parent link="${prefix}_LOWER_LEG"/>
            <child link="${prefix}_FOOT"/>
           
           <xacro:if value="${prefix == 'LF'}">
                <origin xyz="0 ${KFE_2_FOOT_y} ${-KFE_2_FOOT_z}" rpy="0 0 0" />
            </xacro:if>
            <xacro:if value="${prefix == 'LH'}">
                <origin xyz="0 ${KFE_2_FOOT_y} ${-KFE_2_FOOT_z}" rpy="0 0 0" />
            </xacro:if>
            <xacro:if value="${prefix == 'RF'}">
                <origin xyz="0 ${-KFE_2_FOOT_y} ${-KFE_2_FOOT_z}" rpy="0 0 0" />
            </xacro:if>
            <xacro:if value="${prefix == 'RH'}">
                <origin xyz="0 ${-KFE_2_FOOT_y} ${-KFE_2_FOOT_z}" rpy="0 0 0" />
            </xacro:if>


        </joint>
        
        <link name="${prefix}_FOOT">
            <inertial>
                <origin xyz="0 0 0.00035767" rpy="0 0 0" />
                <mass value="0.00693606"/>
                <inertia ixx="0.00000057" ixy="0.0"         ixz="0.0"
                                        iyy="0.00000084" iyz="0.0"
                                                            izz="0.00000053"/>
            </inertial>
            <visual>
                <origin xyz="0 0 0" rpy="0 0 0" />
                <mesh filename="${solo_foot}"/>
            </visual>
            <collision>
                <origin xyz="0 0 0" rpy="0 0 0" />
                <mesh filename="${solo_foot}"/>
            </collision>
        </link>
        <gazebo reference="${prefix}_FOOT">
            <material>Gazebo/Black</material>
            <collision>
                <surface>
                    <friction>
                        <ode>
                            <mu>100</mu>
                            <mu2>100</mu2>
                            <slip1>0</slip1>
                            <slip2>0</slip2>
                        </ode>
                    </friction>
                    <contact>
                        <ode>
                            <kp>1000000.0</kp>
                            <kd>100.0</kd>
                            <min_depth>0.001</min_depth>
                        </ode>
                    </contact>
                </surface>
            </collision>
        </gazebo>-->
  <!--<joint name="{prefix}_HAA_DEBUG" type="fixed">
            <parent name="base_link"/>
            <child name="${prefix}_SHOULDER_DEGUB"/>
            <origin xyz="${base_to_hip_xyz}" rpy="0 0 0"/>
        </joint>

        <link name="${prefix}_SHOULDER_DEBUG" />-->
  <joint name="RH_HAA" type="revolute">
    <parent link="base_link"/>
    <child link="RH_SHOULDER"/>
    <origin rpy="0 0 0" xyz="-0.1946 -0.08750000000000001 0"/>
    <axis xyz="1 0 0"/>
    <limit effort="25" lower="-3.141592" upper="3.141592" velocity="1.5"/>
    <dynamics damping="0.7" friction="100.0"/>
  </joint>
  <link name="RH_SHOULDER">
    <visual>
      <material name="white"/>
      <origin rpy="0 0 0" xyz="-0.01950 0 0"/>
      <geometry>
        <mesh filename="file:///home/jacopo/Documents/mul_pronto_ws/install/solo_robot_description/share/solo_robot_description/urdf/meshes/stl/solo12/solo12_hip_fe_hr.stl"/>
      </geometry>
    </visual>
    <collision>
      <origin rpy="0 0 0" xyz="-0.01950 0 0"/>
      <geometry>
        <mesh filename="file:///home/jacopo/Documents/mul_pronto_ws/install/solo_robot_description/share/solo_robot_description/urdf/meshes/stl/solo12/solo12_hip_fe_hr.stl"/>
      </geometry>
    </collision>
    <inertial>
      <mass value="0.14853845"/>
      <origin rpy="0 0 0" xyz="0.07870700 -0.01 0."/>
      <inertia ixx="0.00003024" ixy="-0.00004671" ixz="0.0" iyy="0.00041193" iyz="0.0" izz="0.00041107"/>
    </inertial>
  </link>
  <joint name="RH_HFE" type="revolute">
    <parent link="RH_SHOULDER"/>
    <child link="RH_UPPER_LEG"/>
    <origin rpy="0 0 0" xyz="0 -0.014 0"/>
    <axis xyz="0 1 0"/>
    <limit effort="25" lower="-3.141592" upper="3.141592" velocity="1.5"/>
    <dynamics damping="0.7" friction="100.0"/>
  </joint>
  <link name="RH_UPPER_LEG">
    <visual>
      <material name="white"/>
      <origin rpy="0 0 0" xyz="0 0 0"/>
      <geometry>
        <mesh filename="file:///home/jacopo/Documents/mul_pronto_ws/install/solo_robot_description/share/solo_robot_description/urdf/meshes/stl/solo12/solo12_upper_leg_right_side.stl"/>
      </geometry>
    </visual>
    <collision>
      <origin rpy="0 0 0" xyz="0 0 0"/>
      <geometry>
        <mesh filename="file:///home/jacopo/Documents/mul_pronto_ws/install/solo_robot_description/share/solo_robot_description/urdf/meshes/stl/solo12/solo12_upper_leg_right_side.stl"/>
      </geometry>
    </collision>
    <inertial>
      <mass value="0.14853845"/>
      <origin rpy="0 0 0" xyz="-0.00001377 -0.01935853 -0.07870700"/>
      <inertia ixx="0.00041107" ixy="0.0" ixz="0.0" iyy="0.00041193" iyz="-0.00004671" izz="0.00003024"/>
    </inertial>
  </link>
  <joint name="RH_KFE" type="revolute">
    <parent link="RH_UPPER_LEG"/>
    <child link="RH_LOWER_LEG"/>
    <origin rpy="0 0 0" xyz="0 -0.037450000000000004 -0.16"/>
    <axis xyz="0 1 0"/>
    <limit effort="25" lower="-3.141592" upper="3.141592" velocity="1.5"/>
    <dynamics damping="0.7" friction="100.0"/>
  </joint>
  <link name="RH_LOWER_LEG">
    <visual>
      <material name="white"/>
      <origin rpy="0 0 0" xyz="0 0 0"/>
      <geometry>
        <mesh filename="file:///home/jacopo/Documents/mul_pronto_ws/install/solo_robot_description/share/solo_robot_description/urdf/meshes/stl/solo12/solo12_lower_leg_right_side.stl"/>
      </geometry>
    </visual>
    <collision name="RH_LOWER_LEG">
      <origin rpy="0 0 0" xyz="0 0 0"/>
      <geometry>
        <mesh filename="file:///home/jacopo/Documents/mul_pronto_ws/install/solo_robot_description/share/solo_robot_description/urdf/meshes/stl/solo12/solo12_lower_leg_right_side.stl"/>
      </geometry>
    </collision>
    <inertial>
      <mass value="0.03070001"/>
      <origin rpy="0 0 0" xyz="0.0 0.00787644 -0.08928215"/>
      <inertia ixx="0.00012024" ixy="0.0" ixz="0.0" iyy="0.00012029" iyz="-0.00000305" izz="0.00000216"/>
    </inertial>
  </link>
  <!--<joint name="${prefix}_ANKLE" type="fixed">
            <parent link="${prefix}_LOWER_LEG"/>
            <child link="${prefix}_FOOT"/>
           
           <xacro:if value="${prefix == 'LF'}">
                <origin xyz="0 ${KFE_2_FOOT_y} ${-KFE_2_FOOT_z}" rpy="0 0 0" />
            </xacro:if>
            <xacro:if value="${prefix == 'LH'}">
                <origin xyz="0 ${KFE_2_FOOT_y} ${-KFE_2_FOOT_z}" rpy="0 0 0" />
            </xacro:if>
            <xacro:if value="${prefix == 'RF'}">
                <origin xyz="0 ${-KFE_2_FOOT_y} ${-KFE_2_FOOT_z}" rpy="0 0 0" />
            </xacro:if>
            <xacro:if value="${prefix == 'RH'}">
                <origin xyz="0 ${-KFE_2_FOOT_y} ${-KFE_2_FOOT_z}" rpy="0 0 0" />
            </xacro:if>


        </joint>
        
        <link name="${prefix}_FOOT">
            <inertial>
                <origin xyz="0 0 0.00035767" rpy="0 0 0" />
                <mass value="0.00693606"/>
                <inertia ixx="0.00000057" ixy="0.0"         ixz="0.0"
                                        iyy="0.00000084" iyz="0.0"
                                                            izz="0.00000053"/>
            </inertial>
            <visual>
                <origin xyz="0 0 0" rpy="0 0 0" />
                <mesh filename="${solo_foot}"/>
            </visual>
            <collision>
                <origin xyz="0 0 0" rpy="0 0 0" />
                <mesh filename="${solo_foot}"/>
            </collision>
        </link>
        <gazebo reference="${prefix}_FOOT">
            <material>Gazebo/Black</material>
            <collision>
                <surface>
                    <friction>
                        <ode>
                            <mu>100</mu>
                            <mu2>100</mu2>
                            <slip1>0</slip1>
                            <slip2>0</slip2>
                        </ode>
                    </friction>
                    <contact>
                        <ode>
                            <kp>1000000.0</kp>
                            <kd>100.0</kd>
                            <min_depth>0.001</min_depth>
                        </ode>
                    </contact>
                </surface>
            </collision>
        </gazebo>-->
  <ros2_control name="SOLO12_WB_Interface" type="system">
    <hardware>
      <plugin>solo12_interface/SOLO12_WB_Interface</plugin>
      <param name="timeout">100</param>
      <param name="command_type">0</param>
      <param name="Kp">10.0</param>
      <param name="Kv">0.0</param>
      <param name="I_saturation">10.0</param>
    </hardware>
  </ros2_control>
  <!--<ros2_control name="SOLO12_Leg_Interface" type="system">
            <hardware>
                <plugin>solo12_interface/SOLO12_Leg_Interface</plugin>
                <param name="timeout" >100</param>
                <param name="command_type" >0</param>
                <param name="Kp" >1.0</param>
                <param name="Kv" >0.001</param>
                <param name="I_saturation" >10.0</param>
            </hardware>
        </ros2_control>-->
</robot>
